Workbook

Sheet Cover
B2: Profound
B3: Five Year Operating Model
B6: HOW THIS MODEL IS BUILT
B7: Revenue is an output, not a target | C7: The hiring plan is the input. Sales capacity, ramp and attrition determine new bookings, and growth falls out.
B8: NRR, GRR and gross margin are outputs | C8: They are computed from retention and expansion drivers and from query volume, then compared against benchmark on the KPIs tab.
B9: Cohorts are dollar denominated | C9: Correct basis for NRR and GRR. A separate logo view uses a worse churn rate and does not feed the ARR calculation.
B10: Every input lives on the Inputs tab | C10: A hardcoded value anywhere else in this workbook is a defect. Change any blue cell and the model recalculates.
B11: Checks ship inside the workbook | C11: The Checks tab reconciles cohorts to the ARR bridge, the deferred revenue roll and the cash roll on every period.
B13: FORMATTING KEY
B14: Hardcoded input | C14: Inputs tab only
B15: Calculation | C15: Formula computed on this sheet
B16: Same sheet reference | C16: Points at another cell on this sheet
B17: Link to another sheet | C17: Cross sheet reference
B19: TAB MAP
B20: Inputs | C20: Every assumption. Scenario switch in cell D5 drives the whole model.
B21: Rev-Capacity | C21: AE hiring, ramp, attrition, productive capacity, new bookings. Self serve.
B22: Rev-Cohorts | C22: Dollar cohort triangle. Renewal events, expansion, churn.
B23: Rev-ARR Bridge | C23: Beginning plus new plus expansion less churn. Agents and self serve.
B24: Headcount | C24: Roster by function, hiring, attrition, payroll, stock compensation.
B25: P&L | C25: Revenue recognition, volume driven cost of revenue, operating expense, EBITDA.
B26: Cash Flow | C26: Billings, deferred revenue, working capital, capital expenditure, cash roll.
B27: KPIs | C27: Computed outputs against benchmark. Runway and raise decision date.
B28: Scenarios | C28: Five cases. Base, upside, downside, downside with hiring freeze, Agents led.
B29: Checks | C29: Live reconciliations. Everything should read OK.

Sheet Inputs
B2: Inputs
B5: SCENARIO SWITCH | D5: 1 | E5: =INDEX({"Base";"Upside";"Downside";"Agents-Led";"Downside + Freeze"},$D$5,1) | F5: 1=Base 2=Upside 3=Downside 4=Downside+Freeze 5=Agents-Led
D7: 2026 | E7: 2027 | F7: 2028 | G7: 2029 | H7: 2030
B8: GIVEN
B9: Opening ARR at 1 Jan 2026 | C9: $ | D9: 55000000 | J9: Given. Interpreted as ending contracted ARR.
B10: Opening cash | C10: $ | D10: 110000000 | J10: Given. Assumed post Series C. No further financing in base case.
B11: Opening headcount | C11: # | D11: 250 | J11: Given.
B12: Minimum cash balance | C12: $ | D12: 25000000 | J12: Given. Board operating floor, not zero. Usable cash is $85M.
B14: OPENING BASE
B15: Enterprise ARR | C15: $ | D15: 53500000 | J15: Ties to given total with self serve below.
B16: Enterprise customers | C16: # | D16: 700 | J16: Public: 700+ enterprise customers. Source: Fortune, February 2026: 700+ enterprise customers at the Series C.
B17: Self serve ARR | C17: $ | D17: 1500000
B18: Self serve customers | C18: # | D18: 500 | J18: Published tiers: $99 and $399 per month.
B20: SALES CAPACITY
B21: Opening quota carrying AEs | C21: # | D21: 30
B22: AE annual quota, fully ramped | C22: $ | D22: 1300000 | J22: Benchmark commercial band $0.9M to $1.4M.
B23: Quota growth per year | C23: % | D23: -0.05 | J23: Negative. Territories thin as the org scales.
J24: Ramp lengthens from four months to five as ACV climbs and Agents makes it a two product sale.
B25: Ramp productivity, month 1 | C25: % | D25: 0.25 | E25: 0.25 | F25: 0.2 | G25: 0.2 | H25: 0.2
B26: Ramp productivity, month 2 | C26: % | D26: 0.5 | E26: 0.5 | F26: 0.4 | G26: 0.4 | H26: 0.4
B27: Ramp productivity, month 3 | C27: % | D27: 0.75 | E27: 0.75 | F27: 0.6 | G27: 0.6 | H27: 0.6
B28: Ramp productivity, month 4 | C28: % | D28: 1 | E28: 1 | F28: 0.8 | G28: 0.8 | H28: 0.8
B29: Ramp productivity, month 5 | C29: % | D29: 1 | E29: 1 | F29: 1 | G29: 1 | H29: 1
B30: Time to hire, months | C30: # | D30: 2 | J30: Benchmark 6 to 10 weeks.
B31: SDRs per AE | C31: x | D31: 0.8
B32: Marketing per AE | C32: x | D32: 0.45
B33: Sales ops per AE | C33: x | D33: 0.3
B34: Enablement per AE | C34: x | D34: 0.05 | J34: Explicit enablement investment holding ramp at the short end.
B36: Quota attainment
B37: Base | C37: % | D37: 0.78 | E37: 0.78 | F37: 0.78 | G37: 0.78 | H37: 0.78
B38: Upside | C38: % | D38: 0.85 | E38: 0.85 | F38: 0.85 | G38: 0.85 | H38: 0.85
B39: Downside | C39: % | D39: 0.74 | E39: 0.74 | F39: 0.74 | G39: 0.74 | H39: 0.74
B40: Agents-Led | C40: % | D40: 0.78 | E40: 0.78 | F40: 0.78 | G40: 0.78 | H40: 0.78
B41: Downside + Freeze | C41: % | D41: 0.74 | E41: 0.74 | F41: 0.74 | G41: 0.74 | H41: 0.74
B42: Active | C42: % | D42: =INDEX($D$37:$H$41,$D$5,1) | E42: =INDEX($D$37:$H$41,$D$5,2) | F42: =INDEX($D$37:$H$41,$D$5,3) | G42: =INDEX($D$37:$H$41,$D$5,4) | H42: =INDEX($D$37:$H$41,$D$5,5) | J42: Benchmark 70% median, 80% top quartile.
B44: AE hires per month
B45: Base | C45: # | D45: 2.2 | E45: 2.6 | F45: 2.8 | G45: 2.6 | H45: 2.2
B46: Upside | C46: # | D46: 4 | E46: 5.2 | F46: 5.8 | G46: 5.8 | H46: 5.2
B47: Downside | C47: # | D47: 2.2 | E47: 2.6 | F47: 2.8 | G47: 2.6 | H47: 2.2
B48: Agents-Led | C48: # | D48: 2.2 | E48: 2.6 | F48: 2.8 | G48: 2.6 | H48: 2.2
...

Sheet Rev-Capacity
B2: Revenue: Sales Capacity and Bookings
B5: Month ending | D5: 46053 | E5: 46081 | F5: 46112 | G5: 46142 | H5: 46173 | I5: 46203 | J5: 46234 | K5: 46265 | L5: 46295 | M5: 46326 | N5: 46356 | O5: 46387 | P5: 46418 | Q5: 46446 | R5: 46477 | S5: 46507 | T5: 46538 | U5: 46568 | V5: 46599 | W5: 46630 | X5: 46660 | Y5: 46691 | Z5: 46721 | AA5: 46752 | AB5: 46783 | AC5: 46812 | AD5: 46843 | AE5: 46873 | AF5: 46904 | AG5: 46934 | AH5: 46965 | AI5: 46996 | AJ5: 47026 | AK5: 47057 | AL5: 47087 | AM5: 47118 | AN5: 47149 | AO5: 47177 | AP5: 47208 | AQ5: 47238 | AR5: 47269 | AS5: 47299 | AT5: 47330 | AU5: 47361 | AV5: 47391 | AW5: 47422 | AX5: 47452 | AY5: 47483 | AZ5: 47514 | BA5: 47542 | BB5: 47573 | BC5: 47603 | BD5: 47634 | BE5: 47664 | BF5: 47695 | BG5: 47726 | BH5: 47756 | BI5: 47787 | BJ5: 47817 | BK5: 47848 | BM5: FY2026 | BN5: FY2027 | BO5: FY2028 | BP5: FY2029 | BQ5: FY2030
B6: Fiscal year | D6: 2026 | E6: 2026 | F6: 2026 | G6: 2026 | H6: 2026 | I6: 2026 | J6: 2026 | K6: 2026 | L6: 2026 | M6: 2026 | N6: 2026 | O6: 2026 | P6: 2027 | Q6: 2027 | R6: 2027 | S6: 2027 | T6: 2027 | U6: 2027 | V6: 2027 | W6: 2027 | X6: 2027 | Y6: 2027 | Z6: 2027 | AA6: 2027 | AB6: 2028 | AC6: 2028 | AD6: 2028 | AE6: 2028 | AF6: 2028 | AG6: 2028 | AH6: 2028 | AI6: 2028 | AJ6: 2028 | AK6: 2028 | AL6: 2028 | AM6: 2028 | AN6: 2029 | AO6: 2029 | AP6: 2029 | AQ6: 2029 | AR6: 2029 | AS6: 2029 | AT6: 2029 | AU6: 2029 | AV6: 2029 | AW6: 2029 | AX6: 2029 | AY6: 2029 | AZ6: 2030 | BA6: 2030 | BB6: 2030 | BC6: 2030 | BD6: 2030 | BE6: 2030 | BF6: 2030 | BG6: 2030 | BH6: 2030 | BI6: 2030 | BJ6: 2030 | BK6: 2030
B7: Period | D7: 1 | E7: 2 | F7: 3 | G7: 4 | H7: 5 | I7: 6 | J7: 7 | K7: 8 | L7: 9 | M7: 10 | N7: 11 | O7: 12 | P7: 13 | Q7: 14 | R7: 15 | S7: 16 | T7: 17 | U7: 18 | V7: 19 | W7: 20 | X7: 21 | Y7: 22 | Z7: 23 | AA7: 24 | AB7: 25 | AC7: 26 | AD7: 27 | AE7: 28 | AF7: 29 | AG7: 30 | AH7: 31 | AI7: 32 | AJ7: 33 | AK7: 34 | AL7: 35 | AM7: 36 | AN7: 37 | AO7: 38 | AP7: 39 | AQ7: 40 | AR7: 41 | AS7: 42 | AT7: 43 | AU7: 44 | AV7: 45 | AW7: 46 | AX7: 47 | AY7: 48 | AZ7: 49 | BA7: 50 | BB7: 51 | BC7: 52 | BD7: 53 | BE7: 54 | BF7: 55 | BG7: 56 | BH7: 57 | BI7: 58 | BJ7: 59 | BK7: 60
B9: QUOTA CARRYING CAPACITY
B10: AE hires arriving | C10: # | D10: =INDEX(Inputs!$D$50:$H$50,1,D$6-2025) | E10: =INDEX(Inputs!$D$50:$H$50,1,D$6-2025) | F10: =INDEX(Inputs!$D$50:$H$50,1,D$6-2025) | G10: =INDEX(Inputs!$D$50:$H$50,1,E$6-2025) | H10: =INDEX(Inputs!$D$50:$H$50,1,F$6-2025) | I10: =INDEX(Inputs!$D$50:$H$50,1,G$6-2025) | J10: =INDEX(Inputs!$D$50:$H$50,1,H$6-2025) | K10: =INDEX(Inputs!$D$50:$H$50,1,I$6-2025) | L10: =INDEX(Inputs!$D$50:$H$50,1,J$6-2025) | M10: =INDEX(Inputs!$D$50:$H$50,1,K$6-2025) | ... BK10: =INDEX(Inputs!$D$50:$H$50,1,BI$6-2025) | BM10: =SUM(D10:O10) | BN10: =SUM(P10:AA10) | BO10: =SUM(AB10:AM10) | BP10: =SUM(AN10:AY10) | BQ10: =SUM(AZ10:BK10)
B11: AE attrition | C11: # | D11: =Inputs!$D$21*Inputs!$D$140/12 | E11: =D12*Inputs!$D$140/12 | F11: =E12*Inputs!$D$140/12 | G11: =F12*Inputs!$D$140/12 | H11: =G12*Inputs!$D$140/12 | I11: =H12*Inputs!$D$140/12 | J11: =I12*Inputs!$D$140/12 | K11: =J12*Inputs!$D$140/12 | L11: =K12*Inputs!$D$140/12 | ... BK11: =BJ12*Inputs!$D$140/12 | BM11: =SUM(D11:O11) | BN11: =SUM(P11:AA11) | BO11: =SUM(AB11:AM11) | BP11: =SUM(AN11:AY11) | BQ11: =SUM(AZ11:BK11)
B12: AE headcount, closing | C12: # | D12: =Inputs!$D$21*(1-Inputs!$D$140/12)+D10 | E12: =D12*(1-Inputs!$D$140/12)+E10 | F12: =E12*(1-Inputs!$D$140/12)+F10 | G12: =F12*(1-Inputs!$D$140/12)+G10 | H12: =G12*(1-Inputs!$D$140/12)+H10 | I12: =H12*(1-Inputs!$D$140/12)+I10 | J12: =I12*(1-Inputs!$D$140/12)+J10 | K12: =J12*(1-Inputs!$D$140/12)+K10 | L12: =K12*(1-Inputs!$D$140/12)+L10 | ... BK12: =BJ12*(1-Inputs!$D$140/12)+BK10 | BM12: =O12 | BN12: =AA12 | BO12: =AM12 | BP12: =AY12 | BQ12: =BK12
B13: Unramped drag | C13: # | D13: =D10*(1-INDEX(Inputs!$D$25:$H$25,1,D$6-2025)) | E13: =E10*(1-INDEX(Inputs!$D$25:$H$25,1,E$6-2025))+D10*(1-INDEX(Inputs!$D$26:$H$26,1,E$6-2025)) | F13: =F10*(1-INDEX(Inputs!$D$25:$H$25,1,F$6-2025))+E10*(1-INDEX(Inputs!$D$26:$H$26,1,F$6-2025))+D10*(1-INDEX(Inputs!$D$27:$H$27,1,F$6-2025)) | G13: =G10*(1-INDEX(Inputs!$D$25:$H$25,1,G$6-2025))+F10*(1-INDEX(Inputs!$D$26:$H$26,1,G$6-2025))+E10*(1-INDEX(Inputs!$D$27:$H$27,1,G$6-2025))+D10*(1-INDEX(Inputs!$D$28:$H$28,1,G$6-2025)) | H13: =H10*(1-INDEX(Inputs!$D$25:$H$25,1,H$6-2025))+G10*(1-INDEX(Inputs!$D$26:$H$26,1,H$6-2025))+F10*(1-INDEX(Inputs!$D$27:$H$27,1,H$6-2025))+E10*(1-INDEX(Inputs!$D$28:$H$28,1,H$6-2025))+D10*(1-INDEX(Inputs!$D$29:$H$29,1,H$6-2025)) | I13: =I10*(1-INDEX(Inputs!$D$25:$H$25,1,I$6-2025))+H10*(1-INDEX(Inputs!$D$26:$H$26,1,I$6-2025))+G10*(1-INDEX(Inputs!$D$27:$H$27,1,I$6-2025))+F10*(1-INDEX(Inputs!$D$28:$H$28,1,I$6-2025))+E10*(1-INDEX(Inputs!$D$29:$H$29,1,I$6-2025)) | J13: =J10*(1-INDEX(Inputs!$D$25:$H$25,1,J$6-2025))+I10*(1-INDEX(Inputs!$D$26:$H$26,1,J$6-2025))+H10*(1-INDEX(Inputs!$D$27:$H$27,1,J$6-2025))+G10*(1-INDEX(Inputs!$D$28:$H$28,1,J$6-2025))+F10*(1-INDEX(Inputs!$D$29:$H$29,1,J$6-2025)) | K13: =K10*(1-INDEX(Inputs!$D$25:$H$25,1,K$6-2025))+J10*(1-INDEX(Inputs!$D$26:$H$26,1,K$6-2025))+I10*(1-INDEX(Inputs!$D$27:$H$27,1,K$6-2025))+H10*(1-INDEX(Inputs!$D$28:$H$28,1,K$6-2025))+G10*(1-INDEX(Inputs!$D$29:$H$29,1,K$6-2025)) | L13: =L10*(1-INDEX(Inputs!$D$25:$H$25,1,L$6-2025))+K10*(1-INDEX(Inputs!$D$26:$H$26,1,L$6-2025))+J10*(1-INDEX(Inputs!$D$27:$H$27,1,L$6-2025))+I10*(1-INDEX(Inputs!$D$28:$H$28,1,L$6-2025))+H10*(1-INDEX(Inputs!$D$29:$H$29,1,L$6-2025)) | M13: =M10*(1-INDEX(Inputs!$D$25:$H$25,1,M$6-2025))+L10*(1-INDEX(Inputs!$D$26:$H$26,1,M$6-2025))+K10*(1-INDEX(Inputs!$D$27:$H$27,1,M$6-2025))+J10*(1-INDEX(Inputs!$D$28:$H$28,1,M$6-2025))+I10*(1-INDEX(Inputs!$D$29:$H$29,1,M$6-2025)) | N13: =N10*(1-INDEX(Inputs!$D$25:$H$25,1,N$6-2025))+M10*(1-INDEX(Inputs!$D$26:$H$26,1,N$6-2025))+L10*(1-INDEX(Inputs!$D$27:$H$27,1,N$6-2025))+K10*(1-INDEX(Inputs!$D$28:$H$28,1,N$6-2025))+J10*(1-INDEX(Inputs!$D$29:$H$29,1,N$6-2025)) | O13: =O10*(1-INDEX(Inputs!$D$25:$H$25,1,O$6-2025))+N10*(1-INDEX(Inputs!$D$26:$H$26,1,O$6-2025))+M10*(1-INDEX(Inputs!$D$27:$H$27,1,O$6-2025))+L10*(1-INDEX(Inputs!$D$28:$H$28,1,O$6-2025))+K10*(1-INDEX(Inputs!$D$29:$H$29,1,O$6-2025)) | ... BK13: =BK10*(1-INDEX(Inputs!$D$25:$H$25,1,BK$6-2025))+BJ10*(1-INDEX(Inputs!$D$26:$H$26,1,BK$6-2025))+BI10*(1-INDEX(Inputs!$D$27:$H$27,1,BK$6-2025))+BH10*(1-INDEX(Inputs!$D$28:$H$28,1,BK$6-2025))+BG10*(1-INDEX(Inputs!$D$29:$H$29,1,BK$6-2025))
B14: Productive AE equivalents | C14: # | D14: =MAX(D12-D13,0) | E14: =MAX(E12-E13,0) | F14: =MAX(F12-F13,0) | G14: =MAX(G12-G13,0) | H14: =MAX(H12-H13,0) | I14: =MAX(I12-I13,0) | J14: =MAX(J12-J13,0) | K14: =MAX(K12-K13,0) | ... BK14: =MAX(BK12-BK13,0) | BM14: =O14 | BN14: =AA14 | BO14: =AM14 | BP14: =AY14 | BQ14: =BK14
B16: SELF SERVE
B17: New customers added | C17: # | D17: =Inputs!$D$82*(1+((1+Inputs!$D$83)^(1/12)-1))^0 | E17: =Inputs!$D$82*(1+((1+Inputs!$D$83)^(1/12)-1))^1 | F17: =Inputs!$D$82*(1+((1+Inputs!$D$83)^(1/12)-1))^2 | G17: =Inputs!$D$82*(1+((1+Inputs!$D$83)^(1/12)-1))^3 | H17: =Inputs!$D$82*(1+((1+Inputs!$D$83)^(1/12)-1))^4 | I17: =Inputs!$D$82*(1+((1+Inputs!$D$83)^(1/12)-1))^5 | J17: =Inputs!$D$82*(1+((1+Inputs!$D$83)^(1/12)-1))^6 | K17: =Inputs!$D$82*(1+((1+Inputs!$D$83)^(1/12)-1))^7 | L17: =Inputs!$D$82*(1+((1+Inputs!$D$83)^(1/12)-1))^8 | M17: =Inputs!$D$82*(1+((1+Inputs!$D$83)^(1/12)-1))^9 | N17: =Inputs!$D$82*(1+((1+Inputs!$D$83)^(1/12)-1))^10 | O17: =Inputs!$D$82*(1+((1+Inputs!$D$83)^(1/12)-1))^11 | P17: =Inputs!$D$82*(1+((1+Inputs!$D$83)^(1/12)-1))^12 | Q17: =Inputs!$D$82*(1+((1+Inputs!$D$83)^(1/12)-1))^13 | R17: =Inputs!$D$82*(1+((1+Inputs!$D$83)^(1/12)-1))^14 | S17: =Inputs!$D$82*(1+((1+Inputs!$D$83)^(1/12)-1))^15 | T17: =Inputs!$D$82*(1+((1+Inputs!$D$83)^(1/12)-1))^16 | U17: =Inputs!$D$82*(1+((1+Inputs!$D$83)^(1/12)-1))^17 | V17: =Inputs!$D$82*(1+((1+Inputs!$D$83)^(1/12)-1))^18 | W17: =Inputs!$D$82*(1+((1+Inputs!$D$83)^(1/12)-1))^19 | X17: =Inputs!$D$82*(1+((1+Inputs!$D$83)^(1/12)-1))^20 | Y17: =Inputs!$D$82*(1+((1+Inputs!$D$83)^(1/12)-1))^21 | Z17: =Inputs!$D$82*(1+((1+Inputs!$D$83)^(1/12)-1))^22 | AA17: =Inputs!$D$82*(1+((1+Inputs!$D$83)^(1/12)-1))^23 | AB17: =Inputs!$D$82*(1+((1+Inputs!$D$83)^(1/12)-1))^24 | AC17: =Inputs!$D$82*(1+((1+Inputs!$D$83)^(1/12)-1))^25 | AD17: =Inputs!$D$82*(1+((1+Inputs!$D$83)^(1/12)-1))^26 | AE17: =Inputs!$D$82*(1+((1+Inputs!$D$83)^(1/12)-1))^27 | AF17: =Inputs!$D$82*(1+((1+Inputs!$D$83)^(1/12)-1))^28 | AG17: =Inputs!$D$82*(1+((1+Inputs!$D$83)^(1/12)-1))^29 | AH17: =Inputs!$D$82*(1+((1+Inputs!$D$83)^(1/12)-1))^30 | AI17: =Inputs!$D$82*(1+((1+Inputs!$D$83)^(1/12)-1))^31 | AJ17: =Inputs!$D$82*(1+((1+Inputs!$D$83)^(1/12)-1))^32 | AK17: =Inputs!$D$82*(1+((1+Inputs!$D$83)^(1/12)-1))^33 | AL17: =Inputs!$D$82*(1+((1+Inputs!$D$83)^(1/12)-1))^34 | AM17: =Inputs!$D$82*(1+((1+Inputs!$D$83)^(1/12)-1))^35 | AN17: =Inputs!$D$82*(1+((1+Inputs!$D$83)^(1/12)-1))^36 | AO17: =Inputs!$D$82*(1+((1+Inputs!$D$83)^(1/12)-1))^37 | AP17: =Inputs!$D$82*(1+((1+Inputs!$D$83)^(1/12)-1))^38 | AQ17: =Inputs!$D$82*(1+((1+Inputs!$D$83)^(1/12)-1))^39 | AR17: =Inputs!$D$82*(1+((1+Inputs!$D$83)^(1/12)-1))^40 | AS17: =Inputs!$D$82*(1+((1+Inputs!$D$83)^(1/12)-1))^41 | AT17: =Inputs!$D$82*(1+((1+Inputs!$D$83)^(1/12)-1))^42 | AU17: =Inputs!$D$82*(1+((1+Inputs!$D$83)^(1/12)-1))^43 | AV17: =Inputs!$D$82*(1+((1+Inputs!$D$83)^(1/12)-1))^44 | AW17: =Inputs!$D$82*(1+((1+Inputs!$D$83)^(1/12)-1))^45 | AX17: =Inputs!$D$82*(1+((1+Inputs!$D$83)^(1/12)-1))^46 | AY17: =Inputs!$D$82*(1+((1+Inputs!$D$83)^(1/12)-1))^47 | AZ17: =Inputs!$D$82*(1+((1+Inputs!$D$83)^(1/12)-1))^48 | BA17: =Inputs!$D$82*(1+((1+Inputs!$D$83)^(1/12)-1))^49 | BB17: =Inputs!$D$82*(1+((1+Inputs!$D$83)^(1/12)-1))^50 | BC17: =Inputs!$D$82*(1+((1+Inputs!$D$83)^(1/12)-1))^51 | BD17: =Inputs!$D$82*(1+((1+Inputs!$D$83)^(1/12)-1))^52 | BE17: =Inputs!$D$82*(1+((1+Inputs!$D$83)^(1/12)-1))^53 | BF17: =Inputs!$D$82*(1+((1+Inputs!$D$83)^(1/12)-1))^54 | BG17: =Inputs!$D$82*(1+((1+Inputs!$D$83)^(1/12)-1))^55 | BH17: =Inputs!$D$82*(1+((1+Inputs!$D$83)^(1/12)-1))^56 | BI17: =Inputs!$D$82*(1+((1+Inputs!$D$83)^(1/12)-1))^57 | BJ17: =Inputs!$D$82*(1+((1+Inputs!$D$83)^(1/12)-1))^58 | BK17: =Inputs!$D$82*(1+((1+Inputs!$D$83)^(1/12)-1))^59
B18: Churned customers | C18: # | D18: =Inputs!$D$18*Inputs!$D$84 | E18: =D20*Inputs!$D$84 | F18: =E20*Inputs!$D$84 | G18: =F20*Inputs!$D$84 | H18: =G20*Inputs!$D$84 | I18: =H20*Inputs!$D$84 | J18: =I20*Inputs!$D$84 | K18: =J20*Inputs!$D$84 | L18: =K20*Inputs!$D$84 | ... BK18: =BJ20*Inputs!$D$84
B19: Converted into enterprise | C19: # | D19: =Inputs!$D$18*Inputs!$D$85 | E19: =D20*Inputs!$D$85 | F19: =E20*Inputs!$D$85 | G19: =F20*Inputs!$D$85 | H19: =G20*Inputs!$D$85 | I19: =H20*Inputs!$D$85 | J19: =I20*Inputs!$D$85 | K19: =J20*Inputs!$D$85 | L19: =K20*Inputs!$D$85 | ... BK19: =BJ20*Inputs!$D$85
B20: Self serve customers, closing | C20: # | D20: =Inputs!$D$18+D17-D18-D19 | E20: =D20+E17-E18-E19 | F20: =E20+F17-F18-F19 | G20: =F20+G17-G18-G19 | H20: =G20+H17-H18-H19 | I20: =H20+I17-I18-I19 | J20: =I20+J17-J18-J19 | K20: =J20+K17-K18-K19 | L20: =K20+L17-L18-L19 | ... BK20: =BJ20+BK17-BK18-BK19 | BM20: =O20 | BN20: =AA20 | BO20: =AM20 | BP20: =AY20 | BQ20: =BK20
B21: Self serve ARR | C21: $ | D21: =D20*Inputs!$D$78*(1+((1+Inputs!$D$79)^(1/12)-1))^0 | E21: =E20*Inputs!$D$78*(1+((1+Inputs!$D$79)^(1/12)-1))^1 | F21: =F20*Inputs!$D$78*(1+((1+Inputs!$D$79)^(1/12)-1))^2 | G21: =G20*Inputs!$D$78*(1+((1+Inputs!$D$79)^(1/12)-1))^3 | H21: =H20*Inputs!$D$78*(1+((1+Inputs!$D$79)^(1/12)-1))^4 | I21: =I20*Inputs!$D$78*(1+((1+Inputs!$D$79)^(1/12)-1))^5 | J21: =J20*Inputs!$D$78*(1+((1+Inputs!$D$79)^(1/12)-1))^6 | K21: =K20*Inputs!$D$78*(1+((1+Inputs!$D$79)^(1/12)-1))^7 | L21: =L20*Inputs!$D$78*(1+((1+Inputs!$D$79)^(1/12)-1))^8 | M21: =M20*Inputs!$D$78*(1+((1+Inputs!$D$79)^(1/12)-1))^9 | N21: =N20*Inputs!$D$78*(1+((1+Inputs!$D$79)^(1/12)-1))^10 | O21: =O20*Inputs!$D$78*(1+((1+Inputs!$D$79)^(1/12)-1))^11 | P21: =P20*Inputs!$D$78*(1+((1+Inputs!$D$79)^(1/12)-1))^12 | Q21: =Q20*Inputs!$D$78*(1+((1+Inputs!$D$79)^(1/12)-1))^13 | R21: =R20*Inputs!$D$78*(1+((1+Inputs!$D$79)^(1/12)-1))^14 | S21: =S20*Inputs!$D$78*(1+((1+Inputs!$D$79)^(1/12)-1))^15 | T21: =T20*Inputs!$D$78*(1+((1+Inputs!$D$79)^(1/12)-1))^16 | U21: =U20*Inputs!$D$78*(1+((1+Inputs!$D$79)^(1/12)-1))^17 | V21: =V20*Inputs!$D$78*(1+((1+Inputs!$D$79)^(1/12)-1))^18 | W21: =W20*Inputs!$D$78*(1+((1+Inputs!$D$79)^(1/12)-1))^19 | X21: =X20*Inputs!$D$78*(1+((1+Inputs!$D$79)^(1/12)-1))^20 | Y21: =Y20*Inputs!$D$78*(1+((1+Inputs!$D$79)^(1/12)-1))^21 | Z21: =Z20*Inputs!$D$78*(1+((1+Inputs!$D$79)^(1/12)-1))^22 | AA21: =AA20*Inputs!$D$78*(1+((1+Inputs!$D$79)^(1/12)-1))^23 | AB21: =AB20*Inputs!$D$78*(1+((1+Inputs!$D$79)^(1/12)-1))^24 | AC21: =AC20*Inputs!$D$78*(1+((1+Inputs!$D$79)^(1/12)-1))^25 | AD21: =AD20*Inputs!$D$78*(1+((1+Inputs!$D$79)^(1/12)-1))^26 | AE21: =AE20*Inputs!$D$78*(1+((1+Inputs!$D$79)^(1/12)-1))^27 | AF21: =AF20*Inputs!$D$78*(1+((1+Inputs!$D$79)^(1/12)-1))^28 | AG21: =AG20*Inputs!$D$78*(1+((1+Inputs!$D$79)^(1/12)-1))^29 | AH21: =AH20*Inputs!$D$78*(1+((1+Inputs!$D$79)^(1/12)-1))^30 | AI21: =AI20*Inputs!$D$78*(1+((1+Inputs!$D$79)^(1/12)-1))^31 | AJ21: =AJ20*Inputs!$D$78*(1+((1+Inputs!$D$79)^(1/12)-1))^32 | AK21: =AK20*Inputs!$D$78*(1+((1+Inputs!$D$79)^(1/12)-1))^33 | AL21: =AL20*Inputs!$D$78*(1+((1+Inputs!$D$79)^(1/12)-1))^34 | AM21: =AM20*Inputs!$D$78*(1+((1+Inputs!$D$79)^(1/12)-1))^35 | AN21: =AN20*Inputs!$D$78*(1+((1+Inputs!$D$79)^(1/12)-1))^36 | AO21: =AO20*Inputs!$D$78*(1+((1+Inputs!$D$79)^(1/12)-1))^37 | AP21: =AP20*Inputs!$D$78*(1+((1+Inputs!$D$79)^(1/12)-1))^38 | AQ21: =AQ20*Inputs!$D$78*(1+((1+Inputs!$D$79)^(1/12)-1))^39 | AR21: =AR20*Inputs!$D$78*(1+((1+Inputs!$D$79)^(1/12)-1))^40 | AS21: =AS20*Inputs!$D$78*(1+((1+Inputs!$D$79)^(1/12)-1))^41 | AT21: =AT20*Inputs!$D$78*(1+((1+Inputs!$D$79)^(1/12)-1))^42 | AU21: =AU20*Inputs!$D$78*(1+((1+Inputs!$D$79)^(1/12)-1))^43 | AV21: =AV20*Inputs!$D$78*(1+((1+Inputs!$D$79)^(1/12)-1))^44 | AW21: =AW20*Inputs!$D$78*(1+((1+Inputs!$D$79)^(1/12)-1))^45 | AX21: =AX20*Inputs!$D$78*(1+((1+Inputs!$D$79)^(1/12)-1))^46 | AY21: =AY20*Inputs!$D$78*(1+((1+Inputs!$D$79)^(1/12)-1))^47 | AZ21: =AZ20*Inputs!$D$78*(1+((1+Inputs!$D$79)^(1/12)-1))^48 | BA21: =BA20*Inputs!$D$78*(1+((1+Inputs!$D$79)^(1/12)-1))^49 | BB21: =BB20*Inputs!$D$78*(1+((1+Inputs!$D$79)^(1/12)-1))^50 | BC21: =BC20*Inputs!$D$78*(1+((1+Inputs!$D$79)^(1/12)-1))^51 | BD21: =BD20*Inputs!$D$78*(1+((1+Inputs!$D$79)^(1/12)-1))^52 | BE21: =BE20*Inputs!$D$78*(1+((1+Inputs!$D$79)^(1/12)-1))^53 | BF21: =BF20*Inputs!$D$78*(1+((1+Inputs!$D$79)^(1/12)-1))^54 | BG21: =BG20*Inputs!$D$78*(1+((1+Inputs!$D$79)^(1/12)-1))^55 | BH21: =BH20*Inputs!$D$78*(1+((1+Inputs!$D$79)^(1/12)-1))^56 | BI21: =BI20*Inputs!$D$78*(1+((1+Inputs!$D$79)^(1/12)-1))^57 | BJ21: =BJ20*Inputs!$D$78*(1+((1+Inputs!$D$79)^(1/12)-1))^58 | BK21: =BK20*Inputs!$D$78*(1+((1+Inputs!$D$79)^(1/12)-1))^59 | BM21: =O21 | BN21: =AA21 | BO21: =AM21 | BP21: =AY21 | BQ21: =BK21
B23: ENTERPRISE BOOKINGS
B24: Quota per AE per month | C24: $ | D24: =Inputs!$D$22*(1+((1+Inputs!$D$23)^(1/12)-1))^0/12 | E24: =Inputs!$D$22*(1+((1+Inputs!$D$23)^(1/12)-1))^1/12 | F24: =Inputs!$D$22*(1+((1+Inputs!$D$23)^(1/12)-1))^2/12 | G24: =Inputs!$D$22*(1+((1+Inputs!$D$23)^(1/12)-1))^3/12 | H24: =Inputs!$D$22*(1+((1+Inputs!$D$23)^(1/12)-1))^4/12 | I24: =Inputs!$D$22*(1+((1+Inputs!$D$23)^(1/12)-1))^5/12 | J24: =Inputs!$D$22*(1+((1+Inputs!$D$23)^(1/12)-1))^6/12 | K24: =Inputs!$D$22*(1+((1+Inputs!$D$23)^(1/12)-1))^7/12 | L24: =Inputs!$D$22*(1+((1+Inputs!$D$23)^(1/12)-1))^8/12 | M24: =Inputs!$D$22*(1+((1+Inputs!$D$23)^(1/12)-1))^9/12 | N24: =Inputs!$D$22*(1+((1+Inputs!$D$23)^(1/12)-1))^10/12 | O24: =Inputs!$D$22*(1+((1+Inputs!$D$23)^(1/12)-1))^11/12 | P24: =Inputs!$D$22*(1+((1+Inputs!$D$23)^(1/12)-1))^12/12 | Q24: =Inputs!$D$22*(1+((1+Inputs!$D$23)^(1/12)-1))^13/12 | R24: =Inputs!$D$22*(1+((1+Inputs!$D$23)^(1/12)-1))^14/12 | S24: =Inputs!$D$22*(1+((1+Inputs!$D$23)^(1/12)-1))^15/12 | T24: =Inputs!$D$22*(1+((1+Inputs!$D$23)^(1/12)-1))^16/12 | U24: =Inputs!$D$22*(1+((1+Inputs!$D$23)^(1/12)-1))^17/12 | V24: =Inputs!$D$22*(1+((1+Inputs!$D$23)^(1/12)-1))^18/12 | W24: =Inputs!$D$22*(1+((1+Inputs!$D$23)^(1/12)-1))^19/12 | X24: =Inputs!$D$22*(1+((1+Inputs!$D$23)^(1/12)-1))^20/12 | Y24: =Inputs!$D$22*(1+((1+Inputs!$D$23)^(1/12)-1))^21/12 | Z24: =Inputs!$D$22*(1+((1+Inputs!$D$23)^(1/12)-1))^22/12 | AA24: =Inputs!$D$22*(1+((1+Inputs!$D$23)^(1/12)-1))^23/12 | AB24: =Inputs!$D$22*(1+((1+Inputs!$D$23)^(1/12)-1))^24/12 | AC24: =Inputs!$D$22*(1+((1+Inputs!$D$23)^(1/12)-1))^25/12 | AD24: =Inputs!$D$22*(1+((1+Inputs!$D$23)^(1/12)-1))^26/12 | AE24: =Inputs!$D$22*(1+((1+Inputs!$D$23)^(1/12)-1))^27/12 | AF24: =Inputs!$D$22*(1+((1+Inputs!$D$23)^(1/12)-1))^28/12 | AG24: =Inputs!$D$22*(1+((1+Inputs!$D$23)^(1/12)-1))^29/12 | AH24: =Inputs!$D$22*(1+((1+Inputs!$D$23)^(1/12)-1))^30/12 | AI24: =Inputs!$D$22*(1+((1+Inputs!$D$23)^(1/12)-1))^31/12 | AJ24: =Inputs!$D$22*(1+((1+Inputs!$D$23)^(1/12)-1))^32/12 | AK24: =Inputs!$D$22*(1+((1+Inputs!$D$23)^(1/12)-1))^33/12 | AL24: =Inputs!$D$22*(1+((1+Inputs!$D$23)^(1/12)-1))^34/12 | AM24: =Inputs!$D$22*(1+((1+Inputs!$D$23)^(1/12)-1))^35/12 | AN24: =Inputs!$D$22*(1+((1+Inputs!$D$23)^(1/12)-1))^36/12 | AO24: =Inputs!$D$22*(1+((1+Inputs!$D$23)^(1/12)-1))^37/12 | AP24: =Inputs!$D$22*(1+((1+Inputs!$D$23)^(1/12)-1))^38/12 | AQ24: =Inputs!$D$22*(1+((1+Inputs!$D$23)^(1/12)-1))^39/12 | AR24: =Inputs!$D$22*(1+((1+Inputs!$D$23)^(1/12)-1))^40/12 | AS24: =Inputs!$D$22*(1+((1+Inputs!$D$23)^(1/12)-1))^41/12 | AT24: =Inputs!$D$22*(1+((1+Inputs!$D$23)^(1/12)-1))^42/12 | AU24: =Inputs!$D$22*(1+((1+Inputs!$D$23)^(1/12)-1))^43/12 | AV24: =Inputs!$D$22*(1+((1+Inputs!$D$23)^(1/12)-1))^44/12 | AW24: =Inputs!$D$22*(1+((1+Inputs!$D$23)^(1/12)-1))^45/12 | AX24: =Inputs!$D$22*(1+((1+Inputs!$D$23)^(1/12)-1))^46/12 | AY24: =Inputs!$D$22*(1+((1+Inputs!$D$23)^(1/12)-1))^47/12 | AZ24: =Inputs!$D$22*(1+((1+Inputs!$D$23)^(1/12)-1))^48/12 | BA24: =Inputs!$D$22*(1+((1+Inputs!$D$23)^(1/12)-1))^49/12 | BB24: =Inputs!$D$22*(1+((1+Inputs!$D$23)^(1/12)-1))^50/12 | BC24: =Inputs!$D$22*(1+((1+Inputs!$D$23)^(1/12)-1))^51/12 | BD24: =Inputs!$D$22*(1+((1+Inputs!$D$23)^(1/12)-1))^52/12 | BE24: =Inputs!$D$22*(1+((1+Inputs!$D$23)^(1/12)-1))^53/12 | BF24: =Inputs!$D$22*(1+((1+Inputs!$D$23)^(1/12)-1))^54/12 | BG24: =Inputs!$D$22*(1+((1+Inputs!$D$23)^(1/12)-1))^55/12 | BH24: =Inputs!$D$22*(1+((1+Inputs!$D$23)^(1/12)-1))^56/12 | BI24: =Inputs!$D$22*(1+((1+Inputs!$D$23)^(1/12)-1))^57/12 | BJ24: =Inputs!$D$22*(1+((1+Inputs!$D$23)^(1/12)-1))^58/12 | BK24: =Inputs!$D$22*(1+((1+Inputs!$D$23)^(1/12)-1))^59/12
B25: Quota attainment | C25: % | D25: =INDEX(Inputs!$D$42:$H$42,1,D$6-2025) | E25: =INDEX(Inputs!$D$42:$H$42,1,E$6-2025) | F25: =INDEX(Inputs!$D$42:$H$42,1,F$6-2025) | G25: =INDEX(Inputs!$D$42:$H$42,1,G$6-2025) | H25: =INDEX(Inputs!$D$42:$H$42,1,H$6-2025) | I25: =INDEX(Inputs!$D$42:$H$42,1,I$6-2025) | J25: =INDEX(Inputs!$D$42:$H$42,1,J$6-2025) | K25: =INDEX(Inputs!$D$42:$H$42,1,K$6-2025) | ... BK25: =INDEX(Inputs!$D$42:$H$42,1,BK$6-2025)
B26: New ARR from sales capacity | C26: $ | D26: =D14*D24*D25 | E26: =E14*E24*E25 | F26: =F14*F24*F25 | G26: =G14*G24*G25 | H26: =H14*H24*H25 | I26: =I14*I24*I25 | J26: =J14*J24*J25 | K26: =K14*K24*K25 | ... BK26: =BK14*BK24*BK25 | BM26: =SUM(D26:O26) | BN26: =SUM(P26:AA26) | BO26: =SUM(AB26:AM26) | BP26: =SUM(AN26:AY26) | BQ26: =SUM(AZ26:BK26)
B27: Enterprise ACV | C27: $ | D27: =Inputs!$D$76*(1+((1+Inputs!$D$77)^(1/12)-1))^0 | E27: =Inputs!$D$76*(1+((1+Inputs!$D$77)^(1/12)-1))^1 | F27: =Inputs!$D$76*(1+((1+Inputs!$D$77)^(1/12)-1))^2 | G27: =Inputs!$D$76*(1+((1+Inputs!$D$77)^(1/12)-1))^3 | H27: =Inputs!$D$76*(1+((1+Inputs!$D$77)^(1/12)-1))^4 | I27: =Inputs!$D$76*(1+((1+Inputs!$D$77)^(1/12)-1))^5 | J27: =Inputs!$D$76*(1+((1+Inputs!$D$77)^(1/12)-1))^6 | K27: =Inputs!$D$76*(1+((1+Inputs!$D$77)^(1/12)-1))^7 | L27: =Inputs!$D$76*(1+((1+Inputs!$D$77)^(1/12)-1))^8 | M27: =Inputs!$D$76*(1+((1+Inputs!$D$77)^(1/12)-1))^9 | N27: =Inputs!$D$76*(1+((1+Inputs!$D$77)^(1/12)-1))^10 | O27: =Inputs!$D$76*(1+((1+Inputs!$D$77)^(1/12)-1))^11 | P27: =Inputs!$D$76*(1+((1+Inputs!$D$77)^(1/12)-1))^12 | Q27: =Inputs!$D$76*(1+((1+Inputs!$D$77)^(1/12)-1))^13 | R27: =Inputs!$D$76*(1+((1+Inputs!$D$77)^(1/12)-1))^14 | S27: =Inputs!$D$76*(1+((1+Inputs!$D$77)^(1/12)-1))^15 | T27: =Inputs!$D$76*(1+((1+Inputs!$D$77)^(1/12)-1))^16 | U27: =Inputs!$D$76*(1+((1+Inputs!$D$77)^(1/12)-1))^17 | V27: =Inputs!$D$76*(1+((1+Inputs!$D$77)^(1/12)-1))^18 | W27: =Inputs!$D$76*(1+((1+Inputs!$D$77)^(1/12)-1))^19 | X27: =Inputs!$D$76*(1+((1+Inputs!$D$77)^(1/12)-1))^20 | Y27: =Inputs!$D$76*(1+((1+Inputs!$D$77)^(1/12)-1))^21 | Z27: =Inputs!$D$76*(1+((1+Inputs!$D$77)^(1/12)-1))^22 | AA27: =Inputs!$D$76*(1+((1+Inputs!$D$77)^(1/12)-1))^23 | AB27: =Inputs!$D$76*(1+((1+Inputs!$D$77)^(1/12)-1))^24 | AC27: =Inputs!$D$76*(1+((1+Inputs!$D$77)^(1/12)-1))^25 | AD27: =Inputs!$D$76*(1+((1+Inputs!$D$77)^(1/12)-1))^26 | AE27: =Inputs!$D$76*(1+((1+Inputs!$D$77)^(1/12)-1))^27 | AF27: =Inputs!$D$76*(1+((1+Inputs!$D$77)^(1/12)-1))^28 | AG27: =Inputs!$D$76*(1+((1+Inputs!$D$77)^(1/12)-1))^29 | AH27: =Inputs!$D$76*(1+((1+Inputs!$D$77)^(1/12)-1))^30 | AI27: =Inputs!$D$76*(1+((1+Inputs!$D$77)^(1/12)-1))^31 | AJ27: =Inputs!$D$76*(1+((1+Inputs!$D$77)^(1/12)-1))^32 | AK27: =Inputs!$D$76*(1+((1+Inputs!$D$77)^(1/12)-1))^33 | AL27: =Inputs!$D$76*(1+((1+Inputs!$D$77)^(1/12)-1))^34 | AM27: =Inputs!$D$76*(1+((1+Inputs!$D$77)^(1/12)-1))^35 | AN27: =Inputs!$D$76*(1+((1+Inputs!$D$77)^(1/12)-1))^36 | AO27: =Inputs!$D$76*(1+((1+Inputs!$D$77)^(1/12)-1))^37 | AP27: =Inputs!$D$76*(1+((1+Inputs!$D$77)^(1/12)-1))^38 | AQ27: =Inputs!$D$76*(1+((1+Inputs!$D$77)^(1/12)-1))^39 | AR27: =Inputs!$D$76*(1+((1+Inputs!$D$77)^(1/12)-1))^40 | AS27: =Inputs!$D$76*(1+((1+Inputs!$D$77)^(1/12)-1))^41 | AT27: =Inputs!$D$76*(1+((1+Inputs!$D$77)^(1/12)-1))^42 | AU27: =Inputs!$D$76*(1+((1+Inputs!$D$77)^(1/12)-1))^43 | AV27: =Inputs!$D$76*(1+((1+Inputs!$D$77)^(1/12)-1))^44 | AW27: =Inputs!$D$76*(1+((1+Inputs!$D$77)^(1/12)-1))^45 | AX27: =Inputs!$D$76*(1+((1+Inputs!$D$77)^(1/12)-1))^46 | AY27: =Inputs!$D$76*(1+((1+Inputs!$D$77)^(1/12)-1))^47 | AZ27: =Inputs!$D$76*(1+((1+Inputs!$D$77)^(1/12)-1))^48 | BA27: =Inputs!$D$76*(1+((1+Inputs!$D$77)^(1/12)-1))^49 | BB27: =Inputs!$D$76*(1+((1+Inputs!$D$77)^(1/12)-1))^50 | BC27: =Inputs!$D$76*(1+((1+Inputs!$D$77)^(1/12)-1))^51 | BD27: =Inputs!$D$76*(1+((1+Inputs!$D$77)^(1/12)-1))^52 | BE27: =Inputs!$D$76*(1+((1+Inputs!$D$77)^(1/12)-1))^53 | BF27: =Inputs!$D$76*(1+((1+Inputs!$D$77)^(1/12)-1))^54 | BG27: =Inputs!$D$76*(1+((1+Inputs!$D$77)^(1/12)-1))^55 | BH27: =Inputs!$D$76*(1+((1+Inputs!$D$77)^(1/12)-1))^56 | BI27: =Inputs!$D$76*(1+((1+Inputs!$D$77)^(1/12)-1))^57 | BJ27: =Inputs!$D$76*(1+((1+Inputs!$D$77)^(1/12)-1))^58 | BK27: =Inputs!$D$76*(1+((1+Inputs!$D$77)^(1/12)-1))^59
B28: New ARR from self serve conversions | C28: $ | D28: =D19*D27 | E28: =E19*E27 | F28: =F19*F27 | G28: =G19*G27 | H28: =H19*H27 | I28: =I19*I27 | J28: =J19*J27 | K28: =K19*K27 | ... BK28: =BK19*BK27 | BM28: =SUM(D28:O28) | BN28: =SUM(P28:AA28) | BO28: =SUM(AB28:AM28) | BP28: =SUM(AN28:AY28) | BQ28: =SUM(AZ28:BK28)
B29: Total new enterprise ARR | C29: $ | D29: =D26+D28 | E29: =E26+E28 | F29: =F26+F28 | G29: =G26+G28 | H29: =H26+H28 | I29: =I26+I28 | J29: =J26+J28 | K29: =K26+K28 | ... BK29: =BK26+BK28 | BM29: =SUM(D29:O29) | BN29: =SUM(P29:AA29) | BO29: =SUM(AB29:AM29) | BP29: =SUM(AN29:AY29) | BQ29: =SUM(AZ29:BK29)
B30: New logos | C30: # | D30: =D29/D27 | E30: =E29/E27 | F30: =F29/F27 | G30: =G29/G27 | H30: =H29/H27 | I30: =I29/I27 | J30: =J29/J27 | K30: =K29/K27 | ... BK30: =BK29/BK27 | BM30: =SUM(D30:O30) | BN30: =SUM(P30:AA30) | BO30: =SUM(AB30:AM30) | BP30: =SUM(AN30:AY30) | BQ30: =SUM(AZ30:BK30)

Sheet Rev-Cohorts
B2: Revenue: Dollar Cohort Triangle
B5: Month ending | D5: 46053 | E5: 46081 | F5: 46112 | G5: 46142 | H5: 46173 | I5: 46203 | J5: 46234 | K5: 46265 | L5: 46295 | M5: 46326 | N5: 46356 | O5: 46387 | P5: 46418 | Q5: 46446 | R5: 46477 | S5: 46507 | T5: 46538 | U5: 46568 | V5: 46599 | W5: 46630 | X5: 46660 | Y5: 46691 | Z5: 46721 | AA5: 46752 | AB5: 46783 | AC5: 46812 | AD5: 46843 | AE5: 46873 | AF5: 46904 | AG5: 46934 | AH5: 46965 | AI5: 46996 | AJ5: 47026 | AK5: 47057 | AL5: 47087 | AM5: 47118 | AN5: 47149 | AO5: 47177 | AP5: 47208 | AQ5: 47238 | AR5: 47269 | AS5: 47299 | AT5: 47330 | AU5: 47361 | AV5: 47391 | AW5: 47422 | AX5: 47452 | AY5: 47483 | AZ5: 47514 | BA5: 47542 | BB5: 47573 | BC5: 47603 | BD5: 47634 | BE5: 47664 | BF5: 47695 | BG5: 47726 | BH5: 47756 | BI5: 47787 | BJ5: 47817 | BK5: 47848 | BM5: FY2026 | BN5: FY2027 | BO5: FY2028 | BP5: FY2029 | BQ5: FY2030
B6: Fiscal year | D6: 2026 | E6: 2026 | F6: 2026 | G6: 2026 | H6: 2026 | I6: 2026 | J6: 2026 | K6: 2026 | L6: 2026 | M6: 2026 | N6: 2026 | O6: 2026 | P6: 2027 | Q6: 2027 | R6: 2027 | S6: 2027 | T6: 2027 | U6: 2027 | V6: 2027 | W6: 2027 | X6: 2027 | Y6: 2027 | Z6: 2027 | AA6: 2027 | AB6: 2028 | AC6: 2028 | AD6: 2028 | AE6: 2028 | AF6: 2028 | AG6: 2028 | AH6: 2028 | AI6: 2028 | AJ6: 2028 | AK6: 2028 | AL6: 2028 | AM6: 2028 | AN6: 2029 | AO6: 2029 | AP6: 2029 | AQ6: 2029 | AR6: 2029 | AS6: 2029 | AT6: 2029 | AU6: 2029 | AV6: 2029 | AW6: 2029 | AX6: 2029 | AY6: 2029 | AZ6: 2030 | BA6: 2030 | BB6: 2030 | BC6: 2030 | BD6: 2030 | BE6: 2030 | BF6: 2030 | BG6: 2030 | BH6: 2030 | BI6: 2030 | BJ6: 2030 | BK6: 2030
B7: Period | D7: 1 | E7: 2 | F7: 3 | G7: 4 | H7: 5 | I7: 6 | J7: 7 | K7: 8 | L7: 9 | M7: 10 | N7: 11 | O7: 12 | P7: 13 | Q7: 14 | R7: 15 | S7: 16 | T7: 17 | U7: 18 | V7: 19 | W7: 20 | X7: 21 | Y7: 22 | Z7: 23 | AA7: 24 | AB7: 25 | AC7: 26 | AD7: 27 | AE7: 28 | AF7: 29 | AG7: 30 | AH7: 31 | AI7: 32 | AJ7: 33 | AK7: 34 | AL7: 35 | AM7: 36 | AN7: 37 | AO7: 38 | AP7: 39 | AQ7: 40 | AR7: 41 | AS7: 42 | AT7: 43 | AU7: 44 | AV7: 45 | AW7: 46 | AX7: 47 | AY7: 48 | AZ7: 49 | BA7: 50 | BB7: 51 | BC7: 52 | BD7: 53 | BE7: 54 | BF7: 55 | BG7: 56 | BH7: 57 | BI7: 58 | BJ7: 59 | BK7: 60
B9: RETENTION DRIVERS
B10: Seat and usage expansion, monthly | C10: % | D10: =(1+INDEX(Inputs!$D$69:$H$69,1,D$6-2025))^(1/12)-1 | E10: =(1+INDEX(Inputs!$D$69:$H$69,1,E$6-2025))^(1/12)-1 | F10: =(1+INDEX(Inputs!$D$69:$H$69,1,F$6-2025))^(1/12)-1 | G10: =(1+INDEX(Inputs!$D$69:$H$69,1,G$6-2025))^(1/12)-1 | H10: =(1+INDEX(Inputs!$D$69:$H$69,1,H$6-2025))^(1/12)-1 | I10: =(1+INDEX(Inputs!$D$69:$H$69,1,I$6-2025))^(1/12)-1 | J10: =(1+INDEX(Inputs!$D$69:$H$69,1,J$6-2025))^(1/12)-1 | K10: =(1+INDEX(Inputs!$D$69:$H$69,1,K$6-2025))^(1/12)-1 | ... BK10: =(1+INDEX(Inputs!$D$69:$H$69,1,BK$6-2025))^(1/12)-1
B11: In contract churn, monthly | C11: % | D11: =Inputs!$D$62/12 | E11: =Inputs!$D$62/12 | F11: =Inputs!$D$62/12 | G11: =Inputs!$D$62/12 | H11: =Inputs!$D$62/12 | I11: =Inputs!$D$62/12 | J11: =Inputs!$D$62/12 | K11: =Inputs!$D$62/12 | ... BK11: =Inputs!$D$62/12
B12: First renewal survival | C12: % | D12: =INDEX(Inputs!$D$59:$H$59,1,D$6-2025) | E12: =INDEX(Inputs!$D$59:$H$59,1,E$6-2025) | F12: =INDEX(Inputs!$D$59:$H$59,1,F$6-2025) | G12: =INDEX(Inputs!$D$59:$H$59,1,G$6-2025) | H12: =INDEX(Inputs!$D$59:$H$59,1,H$6-2025) | I12: =INDEX(Inputs!$D$59:$H$59,1,I$6-2025) | J12: =INDEX(Inputs!$D$59:$H$59,1,J$6-2025) | K12: =INDEX(Inputs!$D$59:$H$59,1,K$6-2025) | ... BK12: =INDEX(Inputs!$D$59:$H$59,1,BK$6-2025)
B13: Later renewal survival | C13: % | D13: =INDEX(Inputs!$D$61:$H$61,1,D$6-2025) | E13: =INDEX(Inputs!$D$61:$H$61,1,E$6-2025) | F13: =INDEX(Inputs!$D$61:$H$61,1,F$6-2025) | G13: =INDEX(Inputs!$D$61:$H$61,1,G$6-2025) | H13: =INDEX(Inputs!$D$61:$H$61,1,H$6-2025) | I13: =INDEX(Inputs!$D$61:$H$61,1,I$6-2025) | J13: =INDEX(Inputs!$D$61:$H$61,1,J$6-2025) | K13: =INDEX(Inputs!$D$61:$H$61,1,K$6-2025) | ... BK13: =INDEX(Inputs!$D$61:$H$61,1,BK$6-2025)
B14: Renewal uplift, price plus cross sell | C14: % | D14: =Inputs!$D$71+INDEX(Inputs!$D$72:$H$72,1,D$6-2025) | E14: =Inputs!$D$71+INDEX(Inputs!$D$72:$H$72,1,E$6-2025) | F14: =Inputs!$D$71+INDEX(Inputs!$D$72:$H$72,1,F$6-2025) | G14: =Inputs!$D$71+INDEX(Inputs!$D$72:$H$72,1,G$6-2025) | H14: =Inputs!$D$71+INDEX(Inputs!$D$72:$H$72,1,H$6-2025) | I14: =Inputs!$D$71+INDEX(Inputs!$D$72:$H$72,1,I$6-2025) | J14: =Inputs!$D$71+INDEX(Inputs!$D$72:$H$72,1,J$6-2025) | K14: =Inputs!$D$71+INDEX(Inputs!$D$72:$H$72,1,K$6-2025) | ... BK14: =Inputs!$D$71+INDEX(Inputs!$D$72:$H$72,1,BK$6-2025)
B16: COHORT TRIANGLE
B17: Opening base, spread evenly across the prior twelve months
B18: Opening slice, age 12 months at start | C18: $ | D18: =Inputs!$D$15/12*(1+D$10)*(1-D$11)*IF(MOD((12+D$7),12)=0,IF((12+D$7)=12,D$12,D$13)*(1+D$14),1) | E18: =D18*(1+E$10)*(1-E$11)*IF(MOD((12+E$7),12)=0,IF((12+E$7)=12,E$12,E$13)*(1+E$14),1) | F18: =E18*(1+F$10)*(1-F$11)*IF(MOD((12+F$7),12)=0,IF((12+F$7)=12,F$12,F$13)*(1+F$14),1) | G18: =F18*(1+G$10)*(1-G$11)*IF(MOD((12+G$7),12)=0,IF((12+G$7)=12,G$12,G$13)*(1+G$14),1) | H18: =G18*(1+H$10)*(1-H$11)*IF(MOD((12+H$7),12)=0,IF((12+H$7)=12,H$12,H$13)*(1+H$14),1) | I18: =H18*(1+I$10)*(1-I$11)*IF(MOD((12+I$7),12)=0,IF((12+I$7)=12,I$12,I$13)*(1+I$14),1) | J18: =I18*(1+J$10)*(1-J$11)*IF(MOD((12+J$7),12)=0,IF((12+J$7)=12,J$12,J$13)*(1+J$14),1) | K18: =J18*(1+K$10)*(1-K$11)*IF(MOD((12+K$7),12)=0,IF((12+K$7)=12,K$12,K$13)*(1+K$14),1) | L18: =K18*(1+L$10)*(1-L$11)*IF(MOD((12+L$7),12)=0,IF((12+L$7)=12,L$12,L$13)*(1+L$14),1) | ... BK18: =BJ18*(1+BK$10)*(1-BK$11)*IF(MOD((12+BK$7),12)=0,IF((12+BK$7)=12,BK$12,BK$13)*(1+BK$14),1)
B19: Opening slice, age 11 months at start | C19: $ | D19: =Inputs!$D$15/12*(1+D$10)*(1-D$11)*IF(MOD((11+D$7),12)=0,IF((11+D$7)=12,D$12,D$13)*(1+D$14),1) | E19: =D19*(1+E$10)*(1-E$11)*IF(MOD((11+E$7),12)=0,IF((11+E$7)=12,E$12,E$13)*(1+E$14),1) | F19: =E19*(1+F$10)*(1-F$11)*IF(MOD((11+F$7),12)=0,IF((11+F$7)=12,F$12,F$13)*(1+F$14),1) | G19: =F19*(1+G$10)*(1-G$11)*IF(MOD((11+G$7),12)=0,IF((11+G$7)=12,G$12,G$13)*(1+G$14),1) | H19: =G19*(1+H$10)*(1-H$11)*IF(MOD((11+H$7),12)=0,IF((11+H$7)=12,H$12,H$13)*(1+H$14),1) | I19: =H19*(1+I$10)*(1-I$11)*IF(MOD((11+I$7),12)=0,IF((11+I$7)=12,I$12,I$13)*(1+I$14),1) | J19: =I19*(1+J$10)*(1-J$11)*IF(MOD((11+J$7),12)=0,IF((11+J$7)=12,J$12,J$13)*(1+J$14),1) | K19: =J19*(1+K$10)*(1-K$11)*IF(MOD((11+K$7),12)=0,IF((11+K$7)=12,K$12,K$13)*(1+K$14),1) | L19: =K19*(1+L$10)*(1-L$11)*IF(MOD((11+L$7),12)=0,IF((11+L$7)=12,L$12,L$13)*(1+L$14),1) | ... BK19: =BJ19*(1+BK$10)*(1-BK$11)*IF(MOD((11+BK$7),12)=0,IF((11+BK$7)=12,BK$12,BK$13)*(1+BK$14),1)
B20: Opening slice, age 10 months at start | C20: $ | D20: =Inputs!$D$15/12*(1+D$10)*(1-D$11)*IF(MOD((10+D$7),12)=0,IF((10+D$7)=12,D$12,D$13)*(1+D$14),1) | E20: =D20*(1+E$10)*(1-E$11)*IF(MOD((10+E$7),12)=0,IF((10+E$7)=12,E$12,E$13)*(1+E$14),1) | F20: =E20*(1+F$10)*(1-F$11)*IF(MOD((10+F$7),12)=0,IF((10+F$7)=12,F$12,F$13)*(1+F$14),1) | G20: =F20*(1+G$10)*(1-G$11)*IF(MOD((10+G$7),12)=0,IF((10+G$7)=12,G$12,G$13)*(1+G$14),1) | H20: =G20*(1+H$10)*(1-H$11)*IF(MOD((10+H$7),12)=0,IF((10+H$7)=12,H$12,H$13)*(1+H$14),1) | I20: =H20*(1+I$10)*(1-I$11)*IF(MOD((10+I$7),12)=0,IF((10+I$7)=12,I$12,I$13)*(1+I$14),1) | J20: =I20*(1+J$10)*(1-J$11)*IF(MOD((10+J$7),12)=0,IF((10+J$7)=12,J$12,J$13)*(1+J$14),1) | K20: =J20*(1+K$10)*(1-K$11)*IF(MOD((10+K$7),12)=0,IF((10+K$7)=12,K$12,K$13)*(1+K$14),1) | L20: =K20*(1+L$10)*(1-L$11)*IF(MOD((10+L$7),12)=0,IF((10+L$7)=12,L$12,L$13)*(1+L$14),1) | ... BK20: =BJ20*(1+BK$10)*(1-BK$11)*IF(MOD((10+BK$7),12)=0,IF((10+BK$7)=12,BK$12,BK$13)*(1+BK$14),1)
B21: Opening slice, age 9 months at start | C21: $ | D21: =Inputs!$D$15/12*(1+D$10)*(1-D$11)*IF(MOD((9+D$7),12)=0,IF((9+D$7)=12,D$12,D$13)*(1+D$14),1) | E21: =D21*(1+E$10)*(1-E$11)*IF(MOD((9+E$7),12)=0,IF((9+E$7)=12,E$12,E$13)*(1+E$14),1) | F21: =E21*(1+F$10)*(1-F$11)*IF(MOD((9+F$7),12)=0,IF((9+F$7)=12,F$12,F$13)*(1+F$14),1) | G21: =F21*(1+G$10)*(1-G$11)*IF(MOD((9+G$7),12)=0,IF((9+G$7)=12,G$12,G$13)*(1+G$14),1) | H21: =G21*(1+H$10)*(1-H$11)*IF(MOD((9+H$7),12)=0,IF((9+H$7)=12,H$12,H$13)*(1+H$14),1) | I21: =H21*(1+I$10)*(1-I$11)*IF(MOD((9+I$7),12)=0,IF((9+I$7)=12,I$12,I$13)*(1+I$14),1) | J21: =I21*(1+J$10)*(1-J$11)*IF(MOD((9+J$7),12)=0,IF((9+J$7)=12,J$12,J$13)*(1+J$14),1) | K21: =J21*(1+K$10)*(1-K$11)*IF(MOD((9+K$7),12)=0,IF((9+K$7)=12,K$12,K$13)*(1+K$14),1) | L21: =K21*(1+L$10)*(1-L$11)*IF(MOD((9+L$7),12)=0,IF((9+L$7)=12,L$12,L$13)*(1+L$14),1) | ... BK21: =BJ21*(1+BK$10)*(1-BK$11)*IF(MOD((9+BK$7),12)=0,IF((9+BK$7)=12,BK$12,BK$13)*(1+BK$14),1)
B22: Opening slice, age 8 months at start | C22: $ | D22: =Inputs!$D$15/12*(1+D$10)*(1-D$11)*IF(MOD((8+D$7),12)=0,IF((8+D$7)=12,D$12,D$13)*(1+D$14),1) | E22: =D22*(1+E$10)*(1-E$11)*IF(MOD((8+E$7),12)=0,IF((8+E$7)=12,E$12,E$13)*(1+E$14),1) | F22: =E22*(1+F$10)*(1-F$11)*IF(MOD((8+F$7),12)=0,IF((8+F$7)=12,F$12,F$13)*(1+F$14),1) | G22: =F22*(1+G$10)*(1-G$11)*IF(MOD((8+G$7),12)=0,IF((8+G$7)=12,G$12,G$13)*(1+G$14),1) | H22: =G22*(1+H$10)*(1-H$11)*IF(MOD((8+H$7),12)=0,IF((8+H$7)=12,H$12,H$13)*(1+H$14),1) | I22: =H22*(1+I$10)*(1-I$11)*IF(MOD((8+I$7),12)=0,IF((8+I$7)=12,I$12,I$13)*(1+I$14),1) | J22: =I22*(1+J$10)*(1-J$11)*IF(MOD((8+J$7),12)=0,IF((8+J$7)=12,J$12,J$13)*(1+J$14),1) | K22: =J22*(1+K$10)*(1-K$11)*IF(MOD((8+K$7),12)=0,IF((8+K$7)=12,K$12,K$13)*(1+K$14),1) | L22: =K22*(1+L$10)*(1-L$11)*IF(MOD((8+L$7),12)=0,IF((8+L$7)=12,L$12,L$13)*(1+L$14),1) | ... BK22: =BJ22*(1+BK$10)*(1-BK$11)*IF(MOD((8+BK$7),12)=0,IF((8+BK$7)=12,BK$12,BK$13)*(1+BK$14),1)
B23: Opening slice, age 7 months at start | C23: $ | D23: =Inputs!$D$15/12*(1+D$10)*(1-D$11)*IF(MOD((7+D$7),12)=0,IF((7+D$7)=12,D$12,D$13)*(1+D$14),1) | E23: =D23*(1+E$10)*(1-E$11)*IF(MOD((7+E$7),12)=0,IF((7+E$7)=12,E$12,E$13)*(1+E$14),1) | F23: =E23*(1+F$10)*(1-F$11)*IF(MOD((7+F$7),12)=0,IF((7+F$7)=12,F$12,F$13)*(1+F$14),1) | G23: =F23*(1+G$10)*(1-G$11)*IF(MOD((7+G$7),12)=0,IF((7+G$7)=12,G$12,G$13)*(1+G$14),1) | H23: =G23*(1+H$10)*(1-H$11)*IF(MOD((7+H$7),12)=0,IF((7+H$7)=12,H$12,H$13)*(1+H$14),1) | I23: =H23*(1+I$10)*(1-I$11)*IF(MOD((7+I$7),12)=0,IF((7+I$7)=12,I$12,I$13)*(1+I$14),1) | J23: =I23*(1+J$10)*(1-J$11)*IF(MOD((7+J$7),12)=0,IF((7+J$7)=12,J$12,J$13)*(1+J$14),1) | K23: =J23*(1+K$10)*(1-K$11)*IF(MOD((7+K$7),12)=0,IF((7+K$7)=12,K$12,K$13)*(1+K$14),1) | L23: =K23*(1+L$10)*(1-L$11)*IF(MOD((7+L$7),12)=0,IF((7+L$7)=12,L$12,L$13)*(1+L$14),1) | ... BK23: =BJ23*(1+BK$10)*(1-BK$11)*IF(MOD((7+BK$7),12)=0,IF((7+BK$7)=12,BK$12,BK$13)*(1+BK$14),1)
B24: Opening slice, age 6 months at start | C24: $ | D24: =Inputs!$D$15/12*(1+D$10)*(1-D$11)*IF(MOD((6+D$7),12)=0,IF((6+D$7)=12,D$12,D$13)*(1+D$14),1) | E24: =D24*(1+E$10)*(1-E$11)*IF(MOD((6+E$7),12)=0,IF((6+E$7)=12,E$12,E$13)*(1+E$14),1) | F24: =E24*(1+F$10)*(1-F$11)*IF(MOD((6+F$7),12)=0,IF((6+F$7)=12,F$12,F$13)*(1+F$14),1) | G24: =F24*(1+G$10)*(1-G$11)*IF(MOD((6+G$7),12)=0,IF((6+G$7)=12,G$12,G$13)*(1+G$14),1) | H24: =G24*(1+H$10)*(1-H$11)*IF(MOD((6+H$7),12)=0,IF((6+H$7)=12,H$12,H$13)*(1+H$14),1) | I24: =H24*(1+I$10)*(1-I$11)*IF(MOD((6+I$7),12)=0,IF((6+I$7)=12,I$12,I$13)*(1+I$14),1) | J24: =I24*(1+J$10)*(1-J$11)*IF(MOD((6+J$7),12)=0,IF((6+J$7)=12,J$12,J$13)*(1+J$14),1) | K24: =J24*(1+K$10)*(1-K$11)*IF(MOD((6+K$7),12)=0,IF((6+K$7)=12,K$12,K$13)*(1+K$14),1) | L24: =K24*(1+L$10)*(1-L$11)*IF(MOD((6+L$7),12)=0,IF((6+L$7)=12,L$12,L$13)*(1+L$14),1) | ... BK24: =BJ24*(1+BK$10)*(1-BK$11)*IF(MOD((6+BK$7),12)=0,IF((6+BK$7)=12,BK$12,BK$13)*(1+BK$14),1)
B25: Opening slice, age 5 months at start | C25: $ | D25: =Inputs!$D$15/12*(1+D$10)*(1-D$11)*IF(MOD((5+D$7),12)=0,IF((5+D$7)=12,D$12,D$13)*(1+D$14),1) | E25: =D25*(1+E$10)*(1-E$11)*IF(MOD((5+E$7),12)=0,IF((5+E$7)=12,E$12,E$13)*(1+E$14),1) | F25: =E25*(1+F$10)*(1-F$11)*IF(MOD((5+F$7),12)=0,IF((5+F$7)=12,F$12,F$13)*(1+F$14),1) | G25: =F25*(1+G$10)*(1-G$11)*IF(MOD((5+G$7),12)=0,IF((5+G$7)=12,G$12,G$13)*(1+G$14),1) | H25: =G25*(1+H$10)*(1-H$11)*IF(MOD((5+H$7),12)=0,IF((5+H$7)=12,H$12,H$13)*(1+H$14),1) | I25: =H25*(1+I$10)*(1-I$11)*IF(MOD((5+I$7),12)=0,IF((5+I$7)=12,I$12,I$13)*(1+I$14),1) | J25: =I25*(1+J$10)*(1-J$11)*IF(MOD((5+J$7),12)=0,IF((5+J$7)=12,J$12,J$13)*(1+J$14),1) | K25: =J25*(1+K$10)*(1-K$11)*IF(MOD((5+K$7),12)=0,IF((5+K$7)=12,K$12,K$13)*(1+K$14),1) | L25: =K25*(1+L$10)*(1-L$11)*IF(MOD((5+L$7),12)=0,IF((5+L$7)=12,L$12,L$13)*(1+L$14),1) | ... BK25: =BJ25*(1+BK$10)*(1-BK$11)*IF(MOD((5+BK$7),12)=0,IF((5+BK$7)=12,BK$12,BK$13)*(1+BK$14),1)
B26: Opening slice, age 4 months at start | C26: $ | D26: =Inputs!$D$15/12*(1+D$10)*(1-D$11)*IF(MOD((4+D$7),12)=0,IF((4+D$7)=12,D$12,D$13)*(1+D$14),1) | E26: =D26*(1+E$10)*(1-E$11)*IF(MOD((4+E$7),12)=0,IF((4+E$7)=12,E$12,E$13)*(1+E$14),1) | F26: =E26*(1+F$10)*(1-F$11)*IF(MOD((4+F$7),12)=0,IF((4+F$7)=12,F$12,F$13)*(1+F$14),1) | G26: =F26*(1+G$10)*(1-G$11)*IF(MOD((4+G$7),12)=0,IF((4+G$7)=12,G$12,G$13)*(1+G$14),1) | H26: =G26*(1+H$10)*(1-H$11)*IF(MOD((4+H$7),12)=0,IF((4+H$7)=12,H$12,H$13)*(1+H$14),1) | I26: =H26*(1+I$10)*(1-I$11)*IF(MOD((4+I$7),12)=0,IF((4+I$7)=12,I$12,I$13)*(1+I$14),1) | J26: =I26*(1+J$10)*(1-J$11)*IF(MOD((4+J$7),12)=0,IF((4+J$7)=12,J$12,J$13)*(1+J$14),1) | K26: =J26*(1+K$10)*(1-K$11)*IF(MOD((4+K$7),12)=0,IF((4+K$7)=12,K$12,K$13)*(1+K$14),1) | L26: =K26*(1+L$10)*(1-L$11)*IF(MOD((4+L$7),12)=0,IF((4+L$7)=12,L$12,L$13)*(1+L$14),1) | ... BK26: =BJ26*(1+BK$10)*(1-BK$11)*IF(MOD((4+BK$7),12)=0,IF((4+BK$7)=12,BK$12,BK$13)*(1+BK$14),1)
B27: Opening slice, age 3 months at start | C27: $ | D27: =Inputs!$D$15/12*(1+D$10)*(1-D$11)*IF(MOD((3+D$7),12)=0,IF((3+D$7)=12,D$12,D$13)*(1+D$14),1) | E27: =D27*(1+E$10)*(1-E$11)*IF(MOD((3+E$7),12)=0,IF((3+E$7)=12,E$12,E$13)*(1+E$14),1) | F27: =E27*(1+F$10)*(1-F$11)*IF(MOD((3+F$7),12)=0,IF((3+F$7)=12,F$12,F$13)*(1+F$14),1) | G27: =F27*(1+G$10)*(1-G$11)*IF(MOD((3+G$7),12)=0,IF((3+G$7)=12,G$12,G$13)*(1+G$14),1) | H27: =G27*(1+H$10)*(1-H$11)*IF(MOD((3+H$7),12)=0,IF((3+H$7)=12,H$12,H$13)*(1+H$14),1) | I27: =H27*(1+I$10)*(1-I$11)*IF(MOD((3+I$7),12)=0,IF((3+I$7)=12,I$12,I$13)*(1+I$14),1) | J27: =I27*(1+J$10)*(1-J$11)*IF(MOD((3+J$7),12)=0,IF((3+J$7)=12,J$12,J$13)*(1+J$14),1) | K27: =J27*(1+K$10)*(1-K$11)*IF(MOD((3+K$7),12)=0,IF((3+K$7)=12,K$12,K$13)*(1+K$14),1) | L27: =K27*(1+L$10)*(1-L$11)*IF(MOD((3+L$7),12)=0,IF((3+L$7)=12,L$12,L$13)*(1+L$14),1) | ... BK27: =BJ27*(1+BK$10)*(1-BK$11)*IF(MOD((3+BK$7),12)=0,IF((3+BK$7)=12,BK$12,BK$13)*(1+BK$14),1)
B28: Opening slice, age 2 months at start | C28: $ | D28: =Inputs!$D$15/12*(1+D$10)*(1-D$11)*IF(MOD((2+D$7),12)=0,IF((2+D$7)=12,D$12,D$13)*(1+D$14),1) | E28: =D28*(1+E$10)*(1-E$11)*IF(MOD((2+E$7),12)=0,IF((2+E$7)=12,E$12,E$13)*(1+E$14),1) | F28: =E28*(1+F$10)*(1-F$11)*IF(MOD((2+F$7),12)=0,IF((2+F$7)=12,F$12,F$13)*(1+F$14),1) | G28: =F28*(1+G$10)*(1-G$11)*IF(MOD((2+G$7),12)=0,IF((2+G$7)=12,G$12,G$13)*(1+G$14),1) | H28: =G28*(1+H$10)*(1-H$11)*IF(MOD((2+H$7),12)=0,IF((2+H$7)=12,H$12,H$13)*(1+H$14),1) | I28: =H28*(1+I$10)*(1-I$11)*IF(MOD((2+I$7),12)=0,IF((2+I$7)=12,I$12,I$13)*(1+I$14),1) | J28: =I28*(1+J$10)*(1-J$11)*IF(MOD((2+J$7),12)=0,IF((2+J$7)=12,J$12,J$13)*(1+J$14),1) | K28: =J28*(1+K$10)*(1-K$11)*IF(MOD((2+K$7),12)=0,IF((2+K$7)=12,K$12,K$13)*(1+K$14),1) | L28: =K28*(1+L$10)*(1-L$11)*IF(MOD((2+L$7),12)=0,IF((2+L$7)=12,L$12,L$13)*(1+L$14),1) | ... BK28: =BJ28*(1+BK$10)*(1-BK$11)*IF(MOD((2+BK$7),12)=0,IF((2+BK$7)=12,BK$12,BK$13)*(1+BK$14),1)
B29: Opening slice, age 1 months at start | C29: $ | D29: =Inputs!$D$15/12*(1+D$10)*(1-D$11)*IF(MOD((1+D$7),12)=0,IF((1+D$7)=12,D$12,D$13)*(1+D$14),1) | E29: =D29*(1+E$10)*(1-E$11)*IF(MOD((1+E$7),12)=0,IF((1+E$7)=12,E$12,E$13)*(1+E$14),1) | F29: =E29*(1+F$10)*(1-F$11)*IF(MOD((1+F$7),12)=0,IF((1+F$7)=12,F$12,F$13)*(1+F$14),1) | G29: =F29*(1+G$10)*(1-G$11)*IF(MOD((1+G$7),12)=0,IF((1+G$7)=12,G$12,G$13)*(1+G$14),1) | H29: =G29*(1+H$10)*(1-H$11)*IF(MOD((1+H$7),12)=0,IF((1+H$7)=12,H$12,H$13)*(1+H$14),1) | I29: =H29*(1+I$10)*(1-I$11)*IF(MOD((1+I$7),12)=0,IF((1+I$7)=12,I$12,I$13)*(1+I$14),1) | J29: =I29*(1+J$10)*(1-J$11)*IF(MOD((1+J$7),12)=0,IF((1+J$7)=12,J$12,J$13)*(1+J$14),1) | K29: =J29*(1+K$10)*(1-K$11)*IF(MOD((1+K$7),12)=0,IF((1+K$7)=12,K$12,K$13)*(1+K$14),1) | L29: =K29*(1+L$10)*(1-L$11)*IF(MOD((1+L$7),12)=0,IF((1+L$7)=12,L$12,L$13)*(1+L$14),1) | ... BK29: =BJ29*(1+BK$10)*(1-BK$11)*IF(MOD((1+BK$7),12)=0,IF((1+BK$7)=12,BK$12,BK$13)*(1+BK$14),1)
B30: New cohorts, one per month of origination
B31: Cohort Jan-26 | C31: $ | D31: ='Rev-Capacity'!D29 | E31: =D31*(1+E$10)*(1-E$11)*IF(MOD((E$7-1),12)=0,IF((E$7-1)=12,E$12,E$13)*(1+E$14),1) | F31: =E31*(1+F$10)*(1-F$11)*IF(MOD((F$7-1),12)=0,IF((F$7-1)=12,F$12,F$13)*(1+F$14),1) | G31: =F31*(1+G$10)*(1-G$11)*IF(MOD((G$7-1),12)=0,IF((G$7-1)=12,G$12,G$13)*(1+G$14),1) | H31: =G31*(1+H$10)*(1-H$11)*IF(MOD((H$7-1),12)=0,IF((H$7-1)=12,H$12,H$13)*(1+H$14),1) | I31: =H31*(1+I$10)*(1-I$11)*IF(MOD((I$7-1),12)=0,IF((I$7-1)=12,I$12,I$13)*(1+I$14),1) | J31: =I31*(1+J$10)*(1-J$11)*IF(MOD((J$7-1),12)=0,IF((J$7-1)=12,J$12,J$13)*(1+J$14),1) | K31: =J31*(1+K$10)*(1-K$11)*IF(MOD((K$7-1),12)=0,IF((K$7-1)=12,K$12,K$13)*(1+K$14),1) | L31: =K31*(1+L$10)*(1-L$11)*IF(MOD((L$7-1),12)=0,IF((L$7-1)=12,L$12,L$13)*(1+L$14),1) | ... BK31: =BJ31*(1+BK$10)*(1-BK$11)*IF(MOD((BK$7-1),12)=0,IF((BK$7-1)=12,BK$12,BK$13)*(1+BK$14),1)
B32: Cohort Feb-26 | C32: $ | D32: =0 | E32: ='Rev-Capacity'!E29 | F32: =E32*(1+F$10)*(1-F$11)*IF(MOD((F$7-2),12)=0,IF((F$7-2)=12,F$12,F$13)*(1+F$14),1) | G32: =F32*(1+G$10)*(1-G$11)*IF(MOD((G$7-2),12)=0,IF((G$7-2)=12,G$12,G$13)*(1+G$14),1) | H32: =G32*(1+H$10)*(1-H$11)*IF(MOD((H$7-2),12)=0,IF((H$7-2)=12,H$12,H$13)*(1+H$14),1) | I32: =H32*(1+I$10)*(1-I$11)*IF(MOD((I$7-2),12)=0,IF((I$7-2)=12,I$12,I$13)*(1+I$14),1) | J32: =I32*(1+J$10)*(1-J$11)*IF(MOD((J$7-2),12)=0,IF((J$7-2)=12,J$12,J$13)*(1+J$14),1) | K32: =J32*(1+K$10)*(1-K$11)*IF(MOD((K$7-2),12)=0,IF((K$7-2)=12,K$12,K$13)*(1+K$14),1) | L32: =K32*(1+L$10)*(1-L$11)*IF(MOD((L$7-2),12)=0,IF((L$7-2)=12,L$12,L$13)*(1+L$14),1) | M32: =L32*(1+M$10)*(1-M$11)*IF(MOD((M$7-2),12)=0,IF((M$7-2)=12,M$12,M$13)*(1+M$14),1) | ... BK32: =BJ32*(1+BK$10)*(1-BK$11)*IF(MOD((BK$7-2),12)=0,IF((BK$7-2)=12,BK$12,BK$13)*(1+BK$14),1)
B33: Cohort Mar-26 | C33: $ | D33: =0 | E33: =0 | F33: ='Rev-Capacity'!F29 | G33: =F33*(1+G$10)*(1-G$11)*IF(MOD((G$7-3),12)=0,IF((G$7-3)=12,G$12,G$13)*(1+G$14),1) | H33: =G33*(1+H$10)*(1-H$11)*IF(MOD((H$7-3),12)=0,IF((H$7-3)=12,H$12,H$13)*(1+H$14),1) | I33: =H33*(1+I$10)*(1-I$11)*IF(MOD((I$7-3),12)=0,IF((I$7-3)=12,I$12,I$13)*(1+I$14),1) | J33: =I33*(1+J$10)*(1-J$11)*IF(MOD((J$7-3),12)=0,IF((J$7-3)=12,J$12,J$13)*(1+J$14),1) | K33: =J33*(1+K$10)*(1-K$11)*IF(MOD((K$7-3),12)=0,IF((K$7-3)=12,K$12,K$13)*(1+K$14),1) | L33: =K33*(1+L$10)*(1-L$11)*IF(MOD((L$7-3),12)=0,IF((L$7-3)=12,L$12,L$13)*(1+L$14),1) | M33: =L33*(1+M$10)*(1-M$11)*IF(MOD((M$7-3),12)=0,IF((M$7-3)=12,M$12,M$13)*(1+M$14),1) | N33: =M33*(1+N$10)*(1-N$11)*IF(MOD((N$7-3),12)=0,IF((N$7-3)=12,N$12,N$13)*(1+N$14),1) | ... BK33: =BJ33*(1+BK$10)*(1-BK$11)*IF(MOD((BK$7-3),12)=0,IF((BK$7-3)=12,BK$12,BK$13)*(1+BK$14),1)
B34: Cohort Apr-26 | C34: $ | D34: =0 | E34: =0 | F34: =0 | G34: ='Rev-Capacity'!G29 | H34: =G34*(1+H$10)*(1-H$11)*IF(MOD((H$7-4),12)=0,IF((H$7-4)=12,H$12,H$13)*(1+H$14),1) | I34: =H34*(1+I$10)*(1-I$11)*IF(MOD((I$7-4),12)=0,IF((I$7-4)=12,I$12,I$13)*(1+I$14),1) | J34: =I34*(1+J$10)*(1-J$11)*IF(MOD((J$7-4),12)=0,IF((J$7-4)=12,J$12,J$13)*(1+J$14),1) | K34: =J34*(1+K$10)*(1-K$11)*IF(MOD((K$7-4),12)=0,IF((K$7-4)=12,K$12,K$13)*(1+K$14),1) | L34: =K34*(1+L$10)*(1-L$11)*IF(MOD((L$7-4),12)=0,IF((L$7-4)=12,L$12,L$13)*(1+L$14),1) | M34: =L34*(1+M$10)*(1-M$11)*IF(MOD((M$7-4),12)=0,IF((M$7-4)=12,M$12,M$13)*(1+M$14),1) | N34: =M34*(1+N$10)*(1-N$11)*IF(MOD((N$7-4),12)=0,IF((N$7-4)=12,N$12,N$13)*(1+N$14),1) | O34: =N34*(1+O$10)*(1-O$11)*IF(MOD((O$7-4),12)=0,IF((O$7-4)=12,O$12,O$13)*(1+O$14),1) | ... BK34: =BJ34*(1+BK$10)*(1-BK$11)*IF(MOD((BK$7-4),12)=0,IF((BK$7-4)=12,BK$12,BK$13)*(1+BK$14),1)
B35: Cohort May-26 | C35: $ | D35: =0 | E35: =0 | F35: =0 | G35: =0 | H35: ='Rev-Capacity'!H29 | I35: =H35*(1+I$10)*(1-I$11)*IF(MOD((I$7-5),12)=0,IF((I$7-5)=12,I$12,I$13)*(1+I$14),1) | J35: =I35*(1+J$10)*(1-J$11)*IF(MOD((J$7-5),12)=0,IF((J$7-5)=12,J$12,J$13)*(1+J$14),1) | K35: =J35*(1+K$10)*(1-K$11)*IF(MOD((K$7-5),12)=0,IF((K$7-5)=12,K$12,K$13)*(1+K$14),1) | L35: =K35*(1+L$10)*(1-L$11)*IF(MOD((L$7-5),12)=0,IF((L$7-5)=12,L$12,L$13)*(1+L$14),1) | M35: =L35*(1+M$10)*(1-M$11)*IF(MOD((M$7-5),12)=0,IF((M$7-5)=12,M$12,M$13)*(1+M$14),1) | N35: =M35*(1+N$10)*(1-N$11)*IF(MOD((N$7-5),12)=0,IF((N$7-5)=12,N$12,N$13)*(1+N$14),1) | O35: =N35*(1+O$10)*(1-O$11)*IF(MOD((O$7-5),12)=0,IF((O$7-5)=12,O$12,O$13)*(1+O$14),1) | P35: =O35*(1+P$10)*(1-P$11)*IF(MOD((P$7-5),12)=0,IF((P$7-5)=12,P$12,P$13)*(1+P$14),1) | ... BK35: =BJ35*(1+BK$10)*(1-BK$11)*IF(MOD((BK$7-5),12)=0,IF((BK$7-5)=12,BK$12,BK$13)*(1+BK$14),1)
B36: Cohort Jun-26 | C36: $ | D36: =0 | E36: =0 | F36: =0 | G36: =0 | H36: =0 | I36: ='Rev-Capacity'!I29 | J36: =I36*(1+J$10)*(1-J$11)*IF(MOD((J$7-6),12)=0,IF((J$7-6)=12,J$12,J$13)*(1+J$14),1) | K36: =J36*(1+K$10)*(1-K$11)*IF(MOD((K$7-6),12)=0,IF((K$7-6)=12,K$12,K$13)*(1+K$14),1) | L36: =K36*(1+L$10)*(1-L$11)*IF(MOD((L$7-6),12)=0,IF((L$7-6)=12,L$12,L$13)*(1+L$14),1) | M36: =L36*(1+M$10)*(1-M$11)*IF(MOD((M$7-6),12)=0,IF((M$7-6)=12,M$12,M$13)*(1+M$14),1) | N36: =M36*(1+N$10)*(1-N$11)*IF(MOD((N$7-6),12)=0,IF((N$7-6)=12,N$12,N$13)*(1+N$14),1) | O36: =N36*(1+O$10)*(1-O$11)*IF(MOD((O$7-6),12)=0,IF((O$7-6)=12,O$12,O$13)*(1+O$14),1) | P36: =O36*(1+P$10)*(1-P$11)*IF(MOD((P$7-6),12)=0,IF((P$7-6)=12,P$12,P$13)*(1+P$14),1) | Q36: =P36*(1+Q$10)*(1-Q$11)*IF(MOD((Q$7-6),12)=0,IF((Q$7-6)=12,Q$12,Q$13)*(1+Q$14),1) | ... BK36: =BJ36*(1+BK$10)*(1-BK$11)*IF(MOD((BK$7-6),12)=0,IF((BK$7-6)=12,BK$12,BK$13)*(1+BK$14),1)
B37: Cohort Jul-26 | C37: $ | D37: =0 | E37: =0 | F37: =0 | G37: =0 | H37: =0 | I37: =0 | J37: ='Rev-Capacity'!J29 | K37: =J37*(1+K$10)*(1-K$11)*IF(MOD((K$7-7),12)=0,IF((K$7-7)=12,K$12,K$13)*(1+K$14),1) | L37: =K37*(1+L$10)*(1-L$11)*IF(MOD((L$7-7),12)=0,IF((L$7-7)=12,L$12,L$13)*(1+L$14),1) | M37: =L37*(1+M$10)*(1-M$11)*IF(MOD((M$7-7),12)=0,IF((M$7-7)=12,M$12,M$13)*(1+M$14),1) | N37: =M37*(1+N$10)*(1-N$11)*IF(MOD((N$7-7),12)=0,IF((N$7-7)=12,N$12,N$13)*(1+N$14),1) | O37: =N37*(1+O$10)*(1-O$11)*IF(MOD((O$7-7),12)=0,IF((O$7-7)=12,O$12,O$13)*(1+O$14),1) | P37: =O37*(1+P$10)*(1-P$11)*IF(MOD((P$7-7),12)=0,IF((P$7-7)=12,P$12,P$13)*(1+P$14),1) | Q37: =P37*(1+Q$10)*(1-Q$11)*IF(MOD((Q$7-7),12)=0,IF((Q$7-7)=12,Q$12,Q$13)*(1+Q$14),1) | R37: =Q37*(1+R$10)*(1-R$11)*IF(MOD((R$7-7),12)=0,IF((R$7-7)=12,R$12,R$13)*(1+R$14),1) | ... BK37: =BJ37*(1+BK$10)*(1-BK$11)*IF(MOD((BK$7-7),12)=0,IF((BK$7-7)=12,BK$12,BK$13)*(1+BK$14),1)
B38: Cohort Aug-26 | C38: $ | D38: =0 | E38: =0 | F38: =0 | G38: =0 | H38: =0 | I38: =0 | J38: =0 | K38: ='Rev-Capacity'!K29 | L38: =K38*(1+L$10)*(1-L$11)*IF(MOD((L$7-8),12)=0,IF((L$7-8)=12,L$12,L$13)*(1+L$14),1) | M38: =L38*(1+M$10)*(1-M$11)*IF(MOD((M$7-8),12)=0,IF((M$7-8)=12,M$12,M$13)*(1+M$14),1) | N38: =M38*(1+N$10)*(1-N$11)*IF(MOD((N$7-8),12)=0,IF((N$7-8)=12,N$12,N$13)*(1+N$14),1) | O38: =N38*(1+O$10)*(1-O$11)*IF(MOD((O$7-8),12)=0,IF((O$7-8)=12,O$12,O$13)*(1+O$14),1) | P38: =O38*(1+P$10)*(1-P$11)*IF(MOD((P$7-8),12)=0,IF((P$7-8)=12,P$12,P$13)*(1+P$14),1) | Q38: =P38*(1+Q$10)*(1-Q$11)*IF(MOD((Q$7-8),12)=0,IF((Q$7-8)=12,Q$12,Q$13)*(1+Q$14),1) | R38: =Q38*(1+R$10)*(1-R$11)*IF(MOD((R$7-8),12)=0,IF((R$7-8)=12,R$12,R$13)*(1+R$14),1) | S38: =R38*(1+S$10)*(1-S$11)*IF(MOD((S$7-8),12)=0,IF((S$7-8)=12,S$12,S$13)*(1+S$14),1) | ... BK38: =BJ38*(1+BK$10)*(1-BK$11)*IF(MOD((BK$7-8),12)=0,IF((BK$7-8)=12,BK$12,BK$13)*(1+BK$14),1)
B39: Cohort Sep-26 | C39: $ | D39: =0 | E39: =0 | F39: =0 | G39: =0 | H39: =0 | I39: =0 | J39: =0 | K39: =0 | L39: ='Rev-Capacity'!L29 | M39: =L39*(1+M$10)*(1-M$11)*IF(MOD((M$7-9),12)=0,IF((M$7-9)=12,M$12,M$13)*(1+M$14),1) | N39: =M39*(1+N$10)*(1-N$11)*IF(MOD((N$7-9),12)=0,IF((N$7-9)=12,N$12,N$13)*(1+N$14),1) | O39: =N39*(1+O$10)*(1-O$11)*IF(MOD((O$7-9),12)=0,IF((O$7-9)=12,O$12,O$13)*(1+O$14),1) | P39: =O39*(1+P$10)*(1-P$11)*IF(MOD((P$7-9),12)=0,IF((P$7-9)=12,P$12,P$13)*(1+P$14),1) | Q39: =P39*(1+Q$10)*(1-Q$11)*IF(MOD((Q$7-9),12)=0,IF((Q$7-9)=12,Q$12,Q$13)*(1+Q$14),1) | R39: =Q39*(1+R$10)*(1-R$11)*IF(MOD((R$7-9),12)=0,IF((R$7-9)=12,R$12,R$13)*(1+R$14),1) | S39: =R39*(1+S$10)*(1-S$11)*IF(MOD((S$7-9),12)=0,IF((S$7-9)=12,S$12,S$13)*(1+S$14),1) | T39: =S39*(1+T$10)*(1-T$11)*IF(MOD((T$7-9),12)=0,IF((T$7-9)=12,T$12,T$13)*(1+T$14),1) | ... BK39: =BJ39*(1+BK$10)*(1-BK$11)*IF(MOD((BK$7-9),12)=0,IF((BK$7-9)=12,BK$12,BK$13)*(1+BK$14),1)
B40: Cohort Oct-26 | C40: $ | D40: =0 | E40: =0 | F40: =0 | G40: =0 | H40: =0 | I40: =0 | J40: =0 | K40: =0 | L40: =0 | M40: ='Rev-Capacity'!M29 | N40: =M40*(1+N$10)*(1-N$11)*IF(MOD((N$7-10),12)=0,IF((N$7-10)=12,N$12,N$13)*(1+N$14),1) | O40: =N40*(1+O$10)*(1-O$11)*IF(MOD((O$7-10),12)=0,IF((O$7-10)=12,O$12,O$13)*(1+O$14),1) | P40: =O40*(1+P$10)*(1-P$11)*IF(MOD((P$7-10),12)=0,IF((P$7-10)=12,P$12,P$13)*(1+P$14),1) | Q40: =P40*(1+Q$10)*(1-Q$11)*IF(MOD((Q$7-10),12)=0,IF((Q$7-10)=12,Q$12,Q$13)*(1+Q$14),1) | R40: =Q40*(1+R$10)*(1-R$11)*IF(MOD((R$7-10),12)=0,IF((R$7-10)=12,R$12,R$13)*(1+R$14),1) | S40: =R40*(1+S$10)*(1-S$11)*IF(MOD((S$7-10),12)=0,IF((S$7-10)=12,S$12,S$13)*(1+S$14),1) | T40: =S40*(1+T$10)*(1-T$11)*IF(MOD((T$7-10),12)=0,IF((T$7-10)=12,T$12,T$13)*(1+T$14),1) | U40: =T40*(1+U$10)*(1-U$11)*IF(MOD((U$7-10),12)=0,IF((U$7-10)=12,U$12,U$13)*(1+U$14),1) | ... BK40: =BJ40*(1+BK$10)*(1-BK$11)*IF(MOD((BK$7-10),12)=0,IF((BK$7-10)=12,BK$12,BK$13)*(1+BK$14),1)
B41: Cohort Nov-26 | C41: $ | D41: =0 | E41: =0 | F41: =0 | G41: =0 | H41: =0 | I41: =0 | J41: =0 | K41: =0 | ... M41: =0 | N41: ='Rev-Capacity'!N29 | O41: =N41*(1+O$10)*(1-O$11)*IF(MOD((O$7-11),12)=0,IF((O$7-11)=12,O$12,O$13)*(1+O$14),1) | P41: =O41*(1+P$10)*(1-P$11)*IF(MOD((P$7-11),12)=0,IF((P$7-11)=12,P$12,P$13)*(1+P$14),1) | Q41: =P41*(1+Q$10)*(1-Q$11)*IF(MOD((Q$7-11),12)=0,IF((Q$7-11)=12,Q$12,Q$13)*(1+Q$14),1) | R41: =Q41*(1+R$10)*(1-R$11)*IF(MOD((R$7-11),12)=0,IF((R$7-11)=12,R$12,R$13)*(1+R$14),1) | S41: =R41*(1+S$10)*(1-S$11)*IF(MOD((S$7-11),12)=0,IF((S$7-11)=12,S$12,S$13)*(1+S$14),1) | T41: =S41*(1+T$10)*(1-T$11)*IF(MOD((T$7-11),12)=0,IF((T$7-11)=12,T$12,T$13)*(1+T$14),1) | U41: =T41*(1+U$10)*(1-U$11)*IF(MOD((U$7-11),12)=0,IF((U$7-11)=12,U$12,U$13)*(1+U$14),1) | V41: =U41*(1+V$10)*(1-V$11)*IF(MOD((V$7-11),12)=0,IF((V$7-11)=12,V$12,V$13)*(1+V$14),1) | ... BK41: =BJ41*(1+BK$10)*(1-BK$11)*IF(MOD((BK$7-11),12)=0,IF((BK$7-11)=12,BK$12,BK$13)*(1+BK$14),1)
B42: Cohort Dec-26 | C42: $ | D42: =0 | E42: =0 | F42: =0 | G42: =0 | H42: =0 | I42: =0 | J42: =0 | K42: =0 | ... N42: =0 | O42: ='Rev-Capacity'!O29 | P42: =O42*(1+P$10)*(1-P$11)*IF(MOD((P$7-12),12)=0,IF((P$7-12)=12,P$12,P$13)*(1+P$14),1) | Q42: =P42*(1+Q$10)*(1-Q$11)*IF(MOD((Q$7-12),12)=0,IF((Q$7-12)=12,Q$12,Q$13)*(1+Q$14),1) | R42: =Q42*(1+R$10)*(1-R$11)*IF(MOD((R$7-12),12)=0,IF((R$7-12)=12,R$12,R$13)*(1+R$14),1) | S42: =R42*(1+S$10)*(1-S$11)*IF(MOD((S$7-12),12)=0,IF((S$7-12)=12,S$12,S$13)*(1+S$14),1) | T42: =S42*(1+T$10)*(1-T$11)*IF(MOD((T$7-12),12)=0,IF((T$7-12)=12,T$12,T$13)*(1+T$14),1) | U42: =T42*(1+U$10)*(1-U$11)*IF(MOD((U$7-12),12)=0,IF((U$7-12)=12,U$12,U$13)*(1+U$14),1) | V42: =U42*(1+V$10)*(1-V$11)*IF(MOD((V$7-12),12)=0,IF((V$7-12)=12,V$12,V$13)*(1+V$14),1) | W42: =V42*(1+W$10)*(1-W$11)*IF(MOD((W$7-12),12)=0,IF((W$7-12)=12,W$12,W$13)*(1+W$14),1) | ... BK42: =BJ42*(1+BK$10)*(1-BK$11)*IF(MOD((BK$7-12),12)=0,IF((BK$7-12)=12,BK$12,BK$13)*(1+BK$14),1)
B43: Cohort Jan-27 | C43: $ | D43: =0 | E43: =0 | F43: =0 | G43: =0 | H43: =0 | I43: =0 | J43: =0 | K43: =0 | ... O43: =0 | P43: ='Rev-Capacity'!P29 | Q43: =P43*(1+Q$10)*(1-Q$11)*IF(MOD((Q$7-13),12)=0,IF((Q$7-13)=12,Q$12,Q$13)*(1+Q$14),1) | R43: =Q43*(1+R$10)*(1-R$11)*IF(MOD((R$7-13),12)=0,IF((R$7-13)=12,R$12,R$13)*(1+R$14),1) | S43: =R43*(1+S$10)*(1-S$11)*IF(MOD((S$7-13),12)=0,IF((S$7-13)=12,S$12,S$13)*(1+S$14),1) | T43: =S43*(1+T$10)*(1-T$11)*IF(MOD((T$7-13),12)=0,IF((T$7-13)=12,T$12,T$13)*(1+T$14),1) | U43: =T43*(1+U$10)*(1-U$11)*IF(MOD((U$7-13),12)=0,IF((U$7-13)=12,U$12,U$13)*(1+U$14),1) | V43: =U43*(1+V$10)*(1-V$11)*IF(MOD((V$7-13),12)=0,IF((V$7-13)=12,V$12,V$13)*(1+V$14),1) | W43: =V43*(1+W$10)*(1-W$11)*IF(MOD((W$7-13),12)=0,IF((W$7-13)=12,W$12,W$13)*(1+W$14),1) | X43: =W43*(1+X$10)*(1-X$11)*IF(MOD((X$7-13),12)=0,IF((X$7-13)=12,X$12,X$13)*(1+X$14),1) | ... BK43: =BJ43*(1+BK$10)*(1-BK$11)*IF(MOD((BK$7-13),12)=0,IF((BK$7-13)=12,BK$12,BK$13)*(1+BK$14),1)
B44: Cohort Feb-27 | C44: $ | D44: =0 | E44: =0 | F44: =0 | G44: =0 | H44: =0 | I44: =0 | J44: =0 | K44: =0 | ... P44: =0 | Q44: ='Rev-Capacity'!Q29 | R44: =Q44*(1+R$10)*(1-R$11)*IF(MOD((R$7-14),12)=0,IF((R$7-14)=12,R$12,R$13)*(1+R$14),1) | S44: =R44*(1+S$10)*(1-S$11)*IF(MOD((S$7-14),12)=0,IF((S$7-14)=12,S$12,S$13)*(1+S$14),1) | T44: =S44*(1+T$10)*(1-T$11)*IF(MOD((T$7-14),12)=0,IF((T$7-14)=12,T$12,T$13)*(1+T$14),1) | U44: =T44*(1+U$10)*(1-U$11)*IF(MOD((U$7-14),12)=0,IF((U$7-14)=12,U$12,U$13)*(1+U$14),1) | V44: =U44*(1+V$10)*(1-V$11)*IF(MOD((V$7-14),12)=0,IF((V$7-14)=12,V$12,V$13)*(1+V$14),1) | W44: =V44*(1+W$10)*(1-W$11)*IF(MOD((W$7-14),12)=0,IF((W$7-14)=12,W$12,W$13)*(1+W$14),1) | X44: =W44*(1+X$10)*(1-X$11)*IF(MOD((X$7-14),12)=0,IF((X$7-14)=12,X$12,X$13)*(1+X$14),1) | Y44: =X44*(1+Y$10)*(1-Y$11)*IF(MOD((Y$7-14),12)=0,IF((Y$7-14)=12,Y$12,Y$13)*(1+Y$14),1) | ... BK44: =BJ44*(1+BK$10)*(1-BK$11)*IF(MOD((BK$7-14),12)=0,IF((BK$7-14)=12,BK$12,BK$13)*(1+BK$14),1)
B45: Cohort Mar-27 | C45: $ | D45: =0 | E45: =0 | F45: =0 | G45: =0 | H45: =0 | I45: =0 | J45: =0 | K45: =0 | ... Q45: =0 | R45: ='Rev-Capacity'!R29 | S45: =R45*(1+S$10)*(1-S$11)*IF(MOD((S$7-15),12)=0,IF((S$7-15)=12,S$12,S$13)*(1+S$14),1) | T45: =S45*(1+T$10)*(1-T$11)*IF(MOD((T$7-15),12)=0,IF((T$7-15)=12,T$12,T$13)*(1+T$14),1) | U45: =T45*(1+U$10)*(1-U$11)*IF(MOD((U$7-15),12)=0,IF((U$7-15)=12,U$12,U$13)*(1+U$14),1) | V45: =U45*(1+V$10)*(1-V$11)*IF(MOD((V$7-15),12)=0,IF((V$7-15)=12,V$12,V$13)*(1+V$14),1) | W45: =V45*(1+W$10)*(1-W$11)*IF(MOD((W$7-15),12)=0,IF((W$7-15)=12,W$12,W$13)*(1+W$14),1) | X45: =W45*(1+X$10)*(1-X$11)*IF(MOD((X$7-15),12)=0,IF((X$7-15)=12,X$12,X$13)*(1+X$14),1) | Y45: =X45*(1+Y$10)*(1-Y$11)*IF(MOD((Y$7-15),12)=0,IF((Y$7-15)=12,Y$12,Y$13)*(1+Y$14),1) | Z45: =Y45*(1+Z$10)*(1-Z$11)*IF(MOD((Z$7-15),12)=0,IF((Z$7-15)=12,Z$12,Z$13)*(1+Z$14),1) | ... BK45: =BJ45*(1+BK$10)*(1-BK$11)*IF(MOD((BK$7-15),12)=0,IF((BK$7-15)=12,BK$12,BK$13)*(1+BK$14),1)
...

Sheet Rev-ARR Bridge
B2: Revenue: ARR Bridge
